Workbook
Name 事件编号列表: 激励事件明细!$A$2:$A$501
Name 税额批次列表: 激励事件明细!$B$2:$B$501
Name 员工编号列表: 计划参数!$I$2:$I$501
Name 员工主数据编号: 计划参数!$I$2:$I$501

Sheet 使用说明
A1: 广电计量股权激励个人所得税计算及分期台账（2026版）
A3: 一、录入顺序 | B3: 先维护计划参数，再逐笔录入激励事件，最后在分期缴税台账登记计划及实际缴税。
A4: 二、颜色 | B4: 蓝色为人工输入；灰色为公告参数；绿色为公式；红色为异常；黄色为说明。
A5: 三、年度计税 | B5: 同一员工同一纳税年度的股权激励所得合并计税，按事件日期及事件编号稳定排序逐笔确认新增税额。
A6: 四、36个月 | B6: 每次事件新增税额独立形成批次，从该事件行权日或解禁日起单独计算36个月。
A7: 五、限制性股票 | B7: 个人获授总数和个人实际出资必须按员工口径录入，公司802万股绝不能作为个人分母。
A8: 六、员工主数据 | B8: 先在计划参数表I:J列维护员工编号和姓名；事件明细员工编号可下拉选择，也允许新增后补录主数据。
A9: 七、分期缴税 | B9: 缴税日期、计划金额和实际金额均可自定义；事件编号或税额批次任填其一，双填时必须指向同一事件。
A10: 八、其他股权激励 | B10: 选择“其他股权激励”时，只需填写其他需合并股权激励所得，不要求数量和市场价。
A11: 九、单人测算 | B11: 该页只引用事件明细、年度汇总和分期台账；事件、缴税、批次余额各25行分页，最多20页。
A12: 十、范围 | B12: 不计算股息红利个人所得税；演示数据仅用于验证公式，不得直接用于申报。
A13: 十一、保护 | B13: 公式及公告参数已启用无密码保护；需要维护时可在Excel“审阅-撤销工作表保护”后操作。
A14: 十二、申报 | B14: 36个月缴税以完成主管税务机关备案为前提，最终申报口径以备案及主管税务机关要求为准。
A17: 演示员工 | B17: DEMO001，两条事件均标注“仅演示”。
A19: 图例 | B19: 人工输入 | C19: 公告参数 | D19: 公式结果 | E19: 异常提示

Sheet 计划参数
A1: 参数类别 | B1: 参数名称 | C1: 参数值 | D1: 生效日 | E1: 失效日 | F1: 口径/说明 | G1: 来源公告 | I1: 员工编号 | J1: 姓名
A2: 基本 | B2: 激励计划 | C2: 2023年股票期权与限制性股票激励计划 | F2: 2023计划 | G2: 2024-035 | I2: DEMO001 | J2: 演示员工
A3: 基本 | B3: 股票代码 | C3: 002967 | F3: 广电计量 | G3: 公司公告
A4: 实际授予 | B4: 股票期权实际授予数量 | C4: 8625000 | D4: 45474 | F4: 623人；授予决定口径 | G4: 2024-043
A5: 完成登记 | B5: 股票期权登记数量 | C5: 8020000 | D5: 45497 | F5: 557人；完成登记口径 | G5: 2024-045
A6: 实际授予 | B6: 限制性股票实际授予数量 | C6: 8625000 | D6: 45474 | F6: 623人；授予决定口径 | G6: 2024-043
A7: 完成登记 | B7: 限制性股票登记数量 | C7: 8020000 | D7: 45531 | F7: 557人；完成登记口径 | G7: 2024-054
A8: 限制性股票 | B8: 登记日 | C8: 45531 | D8: 45531 | F8: 登记完成日及上市日 | G8: 2024-054及后续公告
A9: 限制性股票 | B9: 登记日收盘价 | C9: 13.06 | D9: 45531 | F9: 深交所2024-08-27今收 | G9: 深交所历史行情
A10: 限制性股票 | B10: 授予价格 | C10: 8.68 | D10: 45474 | F10: 仅用于核对个人实际出资 | G10: 2024-043
A11: 个人口径 | B11: 限制性股票个人分母 | C11: 员工实际登记取得总股数 | F11: 802万股不得作为个人分母 | G11: 国税函〔2009〕461号
A12: 行权价格 | B12: 股票期权行权价格 | C12: 14.56 | D12: 45474 | E12: 45666 | F12: 按事件日自动选择 | G12: 2024-043/045
A13: 行权价格 | B13: 股票期权行权价格 | C13: 14.32 | D13: 45667 | E13: 45775 | F13: 按事件日自动选择 | G13: 2025-002
A14: 行权价格 | B14: 股票期权行权价格 | C14: 14.18 | D14: 45776 | E14: 45925 | F14: 按事件日自动选择 | G14: 2025-031
A15: 行权价格 | B15: 股票期权行权价格 | C15: 14.04 | D15: 45926 | F15: 按本任务要求内置至该区间 | G15: 2025-060
I502: 说明 | J502: 员工编号和姓名主数据输入区；可继续新增，事件明细下拉引用本区域。

Sheet 激励事件明细
A1: 事件编号 | B1: 税额批次 | C1: 员工编号 | D1: 姓名 | E1: 激励计划 | F1: 权益类型 | G1: 事件日期 | H1: 纳税年度 | I1: 本次行权或解禁数量 | J1: 行权日或解禁日收盘价 | K1: 适用行权或授予价格 | L1: 限制性股票登记日收盘价 | M1: 员工获授限制性股票总数 | N1: 员工实际出资总额 | O1: 其他需合并股权激励所得 | P1: 离职日期 | Q1: 备案状态 | R1: 备案日期 | S1: 原始本次所得 | T1: 本次应纳税所得额 | U1: 此前年度累计所得 | V1: 本次事件后年度累计所得 | W1: 税率 | X1: 速算扣除数 | Y1: 累计税额 | Z1: 此前累计已确认税额 | AA1: 本次新增税额 | AB1: 本事件纳税义务发生日 | AC1: 事件级36个月截止日 | AD1: 校验 | AE1: 备注 | AF1: 员工首次序号 | AG1: 员工事件序号 | AH1: 员工事件键 | AI1: 年度到期键 | AJ1: 员工到期键 | AK1: 批次有效已缴 | AL1: 批次未缴 | AM1: 年度未缴到期键
A2: DEMO-OPT-001 | B2: =IF(A2="","",A2&"-TAX") -> DEMO-OPT-001-TAX | C2: DEMO001 | D2: 演示员工 | E2: 2023年股票期权与限制性股票激励计划 | F2: 股票期权 | G2: 45666 | H2: =IF(G2="","",YEAR(G2)) -> 2025 | I2: 50000 | J2: 17.8 | K2: =IF(OR(E2="",F2="",G2=""),"",IF(E2<>计划参数!$C$2,"",IF(F2="股票期权",IFERROR(LOOKUP(G2,计划参数!$D$12:$D$15,计划参数!$C$12:$C$15),""),IF(F2="限制性股票",计划参数!$C$10,"")))) -> 14.56 | L2: =IF(AND(E2=计划参数!$C$2,F2="限制性股票",G2>=计划参数!$D$9),计划参数!$C$9,"") | O2: 0 | Q2: 已备案 | R2: 45665 | S2: =IF(OR(A2="",C2="",F2="",G2=""),"",IF(F2="股票期权",IF(OR(I2="",J2="",K2=""),"",(J2-K2)*I2),IF(F2="限制性股票",IF(OR(L2="",M2="",M2<=0,N2=""),"",((L2+J2)/2)*I2-N2*I2/M2),IF(F2="其他股权激励",IF(O2="","",O2),"")))) -> 162000 | T2: =IF(S2="","",MAX(0,S2)) -> 162000 | U2: =IF(T2="","",SUMIFS($T$2:$T$501,$C$2:$C$501,C2,$H$2:$H$501,H2,$G$2:$G$501,"<"&G2)+SUMIFS($T$2:$T$501,$C$2:$C$501,C2,$H$2:$H$501,H2,$G$2:$G$501,G2,$A$2:$A$501,"<"&A2)) -> 0 | V2: =IF(T2="","",U2+T2) -> 162000 | W2: =IF(V2="","",VLOOKUP(V2,税率及规则!$A$2:$C$8,2,TRUE)) -> 0.2 | X2: =IF(V2="","",VLOOKUP(V2,税率及规则!$A$2:$C$8,3,TRUE)) -> 16920 | Y2: =IF(V2="","",MAX(0,V2*W2-X2)) -> 15480 | Z2: =IF(U2="","",MAX(0,U2*VLOOKUP(U2,税率及规则!$A$2:$C$8,2,TRUE)-VLOOKUP(U2,税率及规则!$A$2:$C$8,3,TRUE))) -> 0 | AA2: =IF(Y2="","",MAX(0,Y2-Z2)) -> 15480 | AB2: =IF(G2="","",G2) -> 45666 | AC2: =IF(AB2="","",IF(DAY(AB2)=DAY(EOMONTH(AB2,0)),EOMONTH(EDATE(AB2,36),0),EDATE(AB2,36))) -> 46761 | AD2: =IF(A2="","",IF(COUNTIF($A$2:$A$501,A2)>1,"异常：事件编号重复",IF(OR(C2="",D2="",E2="",F2="",G2=""),"异常：必填项缺失",IF(AND(F2="其他股权激励",O2=""),"异常：其他股权激励所得缺失",IF(AND(F2<>"其他股权激励",OR(I2="",J2="")),"异常：数量或市场价缺失",IF(AND(F2<>"其他股权激励",OR(I2<=0,J2<0)),"异常：数量或价格无效",IF(AND(F2="限制性股票",OR(M2<=0,N2<0,I2>M2)),"异常：个人获授或出资数据无效",IF(AND(IFERROR(INDEX(计划参数!$J$2:$J$501,MATCH(C2,计划参数!$I$2:$I$501,0)),"")<>"",D2<>IFERROR(INDEX(计划参数!$J$2:$J$501,MATCH(C2,计划参数!$I$2:$I$501,0)),"")),"异常：姓名与员工主数据不一致",IF(S2<0,"异常：原始所得为负，已按0计税",IF(OR(AND(F2="股票期权",K2=""),AND(F2="限制性股票",OR(K2="",L2=""))),"异常：计划参数缺失",IF(COUNTIF(计划参数!$I$2:$I$501,C2)=0,"提示：员工编号未在主数据",IF(Q2<>"已备案","提示：未确认备案","正常")))))))))))) -> 正常 | AE2: 仅演示：5万份期权 | AF2: =IF(C2="","",IF(COUNTIF($C$2:C2,C2)=1,MAX($AF$1:AF1)+1,"")) -> 1 | AG2: =IF(C2="","",COUNTIF($C$2:C2,C2)) -> 1 | AH2: =IF(C2="","",C2&"|"&AG2) -> DEMO001|1 | AI2: =IF(OR(A2="",AA2<=0),"",C2&"|"&H2&"|"&(COUNTIFS($C$2:$C$501,C2,$H$2:$H$501,H2,$AA$2:$AA$501,">0",$AC$2:$AC$501,"<"&AC2)+COUNTIFS($C$2:$C$501,C2,$H$2:$H$501,H2,$AA$2:$AA$501,">0",$AC$2:$AC$501,AC2,$A$2:$A$501,"<="&A2))) -> DEMO001|2025|1 | AJ2: =IF(OR(A2="",AA2<=0),"",C2&"|"&(COUNTIFS($C$2:$C$501,C2,$AA$2:$AA$501,">0",$AC$2:$AC$501,"<"&AC2)+COUNTIFS($C$2:$C$501,C2,$AA$2:$AA$501,">0",$AC$2:$AC$501,AC2,$A$2:$A$501,"<="&A2))) -> DEMO001|1 | AK2: =IF(A2="","",SUMIFS(分期缴税台账!$K$2:$K$501,分期缴税台账!$T$2:$T$501,A2,分期缴税台账!$Q$2:$Q$501,"有效")) -> 0 | AL2: =IF(AA2="","",MAX(0,AA2-AK2)) -> 15480 | AM2: =IF(OR(A2="",AL2<=0),"",C2&"|"&H2&"|"&(COUNTIFS($C$2:$C$501,C2,$H$2:$H$501,H2,$AL$2:$AL$501,">0",$AC$2:$AC$501,"<"&AC2)+COUNTIFS($C$2:$C$501,C2,$H$2:$H$501,H2,$AL$2:$AL$501,">0",$AC$2:$AC$501,AC2,$A$2:$A$501,"<="&A2))) -> DEMO001|2025|1
A3: DEMO-RS-001 | B3: =IF(A3="","",A3&"-TAX") -> DEMO-RS-001-TAX | C3: DEMO001 | D3: 演示员工 | E3: 2023年股票期权与限制性股票激励计划 | F3: 限制性股票 | G3: 45838 | H3: =IF(G3="","",YEAR(G3)) -> 2025 | I3: 50000 | J3: 17.8 | K3: =IF(OR(E3="",F3="",G3=""),"",IF(E3<>计划参数!$C$2,"",IF(F3="股票期权",IFERROR(LOOKUP(G3,计划参数!$D$12:$D$15,计划参数!$C$12:$C$15),""),IF(F3="限制性股票",计划参数!$C$10,"")))) -> 8.68 | L3: =IF(AND(E3=计划参数!$C$2,F3="限制性股票",G3>=计划参数!$D$9),计划参数!$C$9,"") -> 13.06 | M3: 50000 | N3: 434000 | O3: 0 | Q3: 已备案 | R3: 45545 | S3: =IF(OR(A3="",C3="",F3="",G3=""),"",IF(F3="股票期权",IF(OR(I3="",J3="",K3=""),"",(J3-K3)*I3),IF(F3="限制性股票",IF(OR(L3="",M3="",M3<=0,N3=""),"",((L3+J3)/2)*I3-N3*I3/M3),IF(F3="其他股权激励",IF(O3="","",O3),"")))) -> 337500 | T3: =IF(S3="","",MAX(0,S3)) -> 337500 | U3: =IF(T3="","",SUMIFS($T$2:$T$501,$C$2:$C$501,C3,$H$2:$H$501,H3,$G$2:$G$501,"<"&G3)+SUMIFS($T$2:$T$501,$C$2:$C$501,C3,$H$2:$H$501,H3,$G$2:$G$501,G3,$A$2:$A$501,"<"&A3)) -> 162000 | V3: =IF(T3="","",U3+T3) -> 499500 | W3: =IF(V3="","",VLOOKUP(V3,税率及规则!$A$2:$C$8,2,TRUE)) -> 0.3 | X3: =IF(V3="","",VLOOKUP(V3,税率及规则!$A$2:$C$8,3,TRUE)) -> 52920 | Y3: =IF(V3="","",MAX(0,V3*W3-X3)) -> 96930 | Z3: =IF(U3="","",MAX(0,U3*VLOOKUP(U3,税率及规则!$A$2:$C$8,2,TRUE)-VLOOKUP(U3,税率及规则!$A$2:$C$8,3,TRUE))) -> 15480 | AA3: =IF(Y3="","",MAX(0,Y3-Z3)) -> 81450 | AB3: =IF(G3="","",G3) -> 45838 | AC3: =IF(AB3="","",IF(DAY(AB3)=DAY(EOMONTH(AB3,0)),EOMONTH(EDATE(AB3,36),0),EDATE(AB3,36))) -> 46934 | AD3: =IF(A3="","",IF(COUNTIF($A$2:$A$501,A3)>1,"异常：事件编号重复",IF(OR(C3="",D3="",E3="",F3="",G3=""),"异常：必填项缺失",IF(AND(F3="其他股权激励",O3=""),"异常：其他股权激励所得缺失",IF(AND(F3<>"其他股权激励",OR(I3="",J3="")),"异常：数量或市场价缺失",IF(AND(F3<>"其他股权激励",OR(I3<=0,J3<0)),"异常：数量或价格无效",IF(AND(F3="限制性股票",OR(M3<=0,N3<0,I3>M3)),"异常：个人获授或出资数据无效",IF(AND(IFERROR(INDEX(计划参数!$J$2:$J$501,MATCH(C3,计划参数!$I$2:$I$501,0)),"")<>"",D3<>IFERROR(INDEX(计划参数!$J$2:$J$501,MATCH(C3,计划参数!$I$2:$I$501,0)),"")),"异常：姓名与员工主数据不一致",IF(S3<0,"异常：原始所得为负，已按0计税",IF(OR(AND(F3="股票期权",K3=""),AND(F3="限制性股票",OR(K3="",L3=""))),"异常：计划参数缺失",IF(COUNTIF(计划参数!$I$2:$I$501,C3)=0,"提示：员工编号未在主数据",IF(Q3<>"已备案","提示：未确认备案","正常")))))))))))) -> 正常 | AE3: 仅演示：5万股限制性股票 | AF3: =IF(C3="","",IF(COUNTIF($C$2:C3,C3)=1,MAX($AF$1:AF2)+1,"")) | AG3: =IF(C3="","",COUNTIF($C$2:C3,C3)) -> 2 | AH3: =IF(C3="","",C3&"|"&AG3) -> DEMO001|2 | AI3: =IF(OR(A3="",AA3<=0),"",C3&"|"&H3&"|"&(COUNTIFS($C$2:$C$501,C3,$H$2:$H$501,H3,$AA$2:$AA$501,">0",$AC$2:$AC$501,"<"&AC3)+COUNTIFS($C$2:$C$501,C3,$H$2:$H$501,H3,$AA$2:$AA$501,">0",$AC$2:$AC$501,AC3,$A$2:$A$501,"<="&A3))) -> DEMO001|2025|2 | AJ3: =IF(OR(A3="",AA3<=0),"",C3&"|"&(COUNTIFS($C$2:$C$501,C3,$AA$2:$AA$501,">0",$AC$2:$AC$501,"<"&AC3)+COUNTIFS($C$2:$C$501,C3,$AA$2:$AA$501,">0",$AC$2:$AC$501,AC3,$A$2:$A$501,"<="&A3))) -> DEMO001|2 | AK3: =IF(A3="","",SUMIFS(分期缴税台账!$K$2:$K$501,分期缴税台账!$T$2:$T$501,A3,分期缴税台账!$Q$2:$Q$501,"有效")) -> 0 | AL3: =IF(AA3="","",MAX(0,AA3-AK3)) -> 81450 | AM3: =IF(OR(A3="",AL3<=0),"",C3&"|"&H3&"|"&(COUNTIFS($C$2:$C$501,C3,$H$2:$H$501,H3,$AL$2:$AL$501,">0",$AC$2:$AC$501,"<"&AC3)+COUNTIFS($C$2:$C$501,C3,$H$2:$H$501,H3,$AL$2:$AL$501,">0",$AC$2:$AC$501,AC3,$A$2:$A$501,"<="&A3))) -> DEMO001|2025|2
B4: =IF(A4="","",A4&"-TAX") | H4: =IF(G4="","",YEAR(G4)) | K4: =IF(OR(E4="",F4="",G4=""),"",IF(E4<>计划参数!$C$2,"",IF(F4="股票期权",IFERROR(LOOKUP(G4,计划参数!$D$12:$D$15,计划参数!$C$12:$C$15),""),IF(F4="限制性股票",计划参数!$C$10,"")))) | L4: =IF(AND(E4=计划参数!$C$2,F4="限制性股票",G4>=计划参数!$D$9),计划参数!$C$9,"") | S4: =IF(OR(A4="",C4="",F4="",G4=""),"",IF(F4="股票期权",IF(OR(I4="",J4="",K4=""),"",(J4-K4)*I4),IF(F4="限制性股票",IF(OR(L4="",M4="",M4<=0,N4=""),"",((L4+J4)/2)*I4-N4*I4/M4),IF(F4="其他股权激励",IF(O4="","",O4),"")))) | T4: =IF(S4="","",MAX(0,S4)) | U4: =IF(T4="","",SUMIFS($T$2:$T$501,$C$2:$C$501,C4,$H$2:$H$501,H4,$G$2:$G$501,"<"&G4)+SUMIFS($T$2:$T$501,$C$2:$C$501,C4,$H$2:$H$501,H4,$G$2:$G$501,G4,$A$2:$A$501,"<"&A4)) | V4: =IF(T4="","",U4+T4) | W4: =IF(V4="","",VLOOKUP(V4,税率及规则!$A$2:$C$8,2,TRUE)) | X4: =IF(V4="","",VLOOKUP(V4,税率及规则!$A$2:$C$8,3,TRUE)) | Y4: =IF(V4="","",MAX(0,V4*W4-X4)) | Z4: =IF(U4="","",MAX(0,U4*VLOOKUP(U4,税率及规则!$A$2:$C$8,2,TRUE)-VLOOKUP(U4,税率及规则!$A$2:$C$8,3,TRUE))) | AA4: =IF(Y4="","",MAX(0,Y4-Z4)) | AB4: =IF(G4="","",G4) | AC4: =IF(AB4="","",IF(DAY(AB4)=DAY(EOMONTH(AB4,0)),EOMONTH(EDATE(AB4,36),0),EDATE(AB4,36))) | AD4: =IF(A4="","",IF(COUNTIF($A$2:$A$501,A4)>1,"异常：事件编号重复",IF(OR(C4="",D4="",E4="",F4="",G4=""),"异常：必填项缺失",IF(AND(F4="其他股权激励",O4=""),"异常：其他股权激励所得缺失",IF(AND(F4<>"其他股权激励",OR(I4="",J4="")),"异常：数量或市场价缺失",IF(AND(F4<>"其他股权激励",OR(I4<=0,J4<0)),"异常：数量或价格无效",IF(AND(F4="限制性股票",OR(M4<=0,N4<0,I4>M4)),"异常：个人获授或出资数据无效",IF(AND(IFERROR(INDEX(计划参数!$J$2:$J$501,MATCH(C4,计划参数!$I$2:$I$501,0)),"")<>"",D4<>IFERROR(INDEX(计划参数!$J$2:$J$501,MATCH(C4,计划参数!$I$2:$I$501,0)),"")),"异常：姓名与员工主数据不一致",IF(S4<0,"异常：原始所得为负，已按0计税",IF(OR(AND(F4="股票期权",K4=""),AND(F4="限制性股票",OR(K4="",L4=""))),"异常：计划参数缺失",IF(COUNTIF(计划参数!$I$2:$I$501,C4)=0,"提示：员工编号未在主数据",IF(Q4<>"已备案","提示：未确认备案","正常")))))))))))) | AF4: =IF(C4="","",IF(COUNTIF($C$2:C4,C4)=1,MAX($AF$1:AF3)+1,"")) | AG4: =IF(C4="","",COUNTIF($C$2:C4,C4)) | AH4: =IF(C4="","",C4&"|"&AG4) | AI4: =IF(OR(A4="",AA4<=0),"",C4&"|"&H4&"|"&(COUNTIFS($C$2:$C$501,C4,$H$2:$H$501,H4,$AA$2:$AA$501,">0",$AC$2:$AC$501,"<"&AC4)+COUNTIFS($C$2:$C$501,C4,$H$2:$H$501,H4,$AA$2:$AA$501,">0",$AC$2:$AC$501,AC4,$A$2:$A$501,"<="&A4))) | AJ4: =IF(OR(A4="",AA4<=0),"",C4&"|"&(COUNTIFS($C$2:$C$501,C4,$AA$2:$AA$501,">0",$AC$2:$AC$501,"<"&AC4)+COUNTIFS($C$2:$C$501,C4,$AA$2:$AA$501,">0",$AC$2:$AC$501,AC4,$A$2:$A$501,"<="&A4))) | AK4: =IF(A4="","",SUMIFS(分期缴税台账!$K$2:$K$501,分期缴税台账!$T$2:$T$501,A4,分期缴税台账!$Q$2:$Q$501,"有效")) | AL4: =IF(AA4="","",MAX(0,AA4-AK4)) | AM4: =IF(OR(A4="",AL4<=0),"",C4&"|"&H4&"|"&(COUNTIFS($C$2:$C$501,C4,$H$2:$H$501,H4,$AL$2:$AL$501,">0",$AC$2:$AC$501,"<"&AC4)+COUNTIFS($C$2:$C$501,C4,$H$2:$H$501,H4,$AL$2:$AL$501,">0",$AC$2:$AC$501,AC4,$A$2:$A$501,"<="&A4)))
B5: =IF(A5="","",A5&"-TAX") | H5: =IF(G5="","",YEAR(G5)) | K5: =IF(OR(E5="",F5="",G5=""),"",IF(E5<>计划参数!$C$2,"",IF(F5="股票期权",IFERROR(LOOKUP(G5,计划参数!$D$12:$D$15,计划参数!$C$12:$C$15),""),IF(F5="限制性股票",计划参数!$C$10,"")))) | L5: =IF(AND(E5=计划参数!$C$2,F5="限制性股票",G5>=计划参数!$D$9),计划参数!$C$9,"") | S5: =IF(OR(A5="",C5="",F5="",G5=""),"",IF(F5="股票期权",IF(OR(I5="",J5="",K5=""),"",(J5-K5)*I5),IF(F5="限制性股票",IF(OR(L5="",M5="",M5<=0,N5=""),"",((L5+J5)/2)*I5-N5*I5/M5),IF(F5="其他股权激励",IF(O5="","",O5),"")))) | T5: =IF(S5="","",MAX(0,S5)) | U5: =IF(T5="","",SUMIFS($T$2:$T$501,$C$2:$C$501,C5,$H$2:$H$501,H5,$G$2:$G$501,"<"&G5)+SUMIFS($T$2:$T$501,$C$2:$C$501,C5,$H$2:$H$501,H5,$G$2:$G$501,G5,$A$2:$A$501,"<"&A5)) | V5: =IF(T5="","",U5+T5) | W5: =IF(V5="","",VLOOKUP(V5,税率及规则!$A$2:$C$8,2,TRUE)) | X5: =IF(V5="","",VLOOKUP(V5,税率及规则!$A$2:$C$8,3,TRUE)) | Y5: =IF(V5="","",MAX(0,V5*W5-X5)) | Z5: =IF(U5="","",MAX(0,U5*VLOOKUP(U5,税率及规则!$A$2:$C$8,2,TRUE)-VLOOKUP(U5,税率及规则!$A$2:$C$8,3,TRUE))) | AA5: =IF(Y5="","",MAX(0,Y5-Z5)) | AB5: =IF(G5="","",G5) | AC5: =IF(AB5="","",IF(DAY(AB5)=DAY(EOMONTH(AB5,0)),EOMONTH(EDATE(AB5,36),0),EDATE(AB5,36))) | AD5: =IF(A5="","",IF(COUNTIF($A$2:$A$501,A5)>1,"异常：事件编号重复",IF(OR(C5="",D5="",E5="",F5="",G5=""),"异常：必填项缺失",IF(AND(F5="其他股权激励",O5=""),"异常：其他股权激励所得缺失",IF(AND(F5<>"其他股权激励",OR(I5="",J5="")),"异常：数量或市场价缺失",IF(AND(F5<>"其他股权激励",OR(I5<=0,J5<0)),"异常：数量或价格无效",IF(AND(F5="限制性股票",OR(M5<=0,N5<0,I5>M5)),"异常：个人获授或出资数据无效",IF(AND(IFERROR(INDEX(计划参数!$J$2:$J$501,MATCH(C5,计划参数!$I$2:$I$501,0)),"")<>"",D5<>IFERROR(INDEX(计划参数!$J$2:$J$501,MATCH(C5,计划参数!$I$2:$I$501,0)),"")),"异常：姓名与员工主数据不一致",IF(S5<0,"异常：原始所得为负，已按0计税",IF(OR(AND(F5="股票期权",K5=""),AND(F5="限制性股票",OR(K5="",L5=""))),"异常：计划参数缺失",IF(COUNTIF(计划参数!$I$2:$I$501,C5)=0,"提示：员工编号未在主数据",IF(Q5<>"已备案","提示：未确认备案","正常")))))))))))) | AF5: =IF(C5="","",IF(COUNTIF($C$2:C5,C5)=1,MAX($AF$1:AF4)+1,"")) | AG5: =IF(C5="","",COUNTIF($C$2:C5,C5)) | AH5: =IF(C5="","",C5&"|"&AG5) | AI5: =IF(OR(A5="",AA5<=0),"",C5&"|"&H5&"|"&(COUNTIFS($C$2:$C$501,C5,$H$2:$H$501,H5,$AA$2:$AA$501,">0",$AC$2:$AC$501,"<"&AC5)+COUNTIFS($C$2:$C$501,C5,$H$2:$H$501,H5,$AA$2:$AA$501,">0",$AC$2:$AC$501,AC5,$A$2:$A$501,"<="&A5))) | AJ5: =IF(OR(A5="",AA5<=0),"",C5&"|"&(COUNTIFS($C$2:$C$501,C5,$AA$2:$AA$501,">0",$AC$2:$AC$501,"<"&AC5)+COUNTIFS($C$2:$C$501,C5,$AA$2:$AA$501,">0",$AC$2:$AC$501,AC5,$A$2:$A$501,"<="&A5))) | AK5: =IF(A5="","",SUMIFS(分期缴税台账!$K$2:$K$501,分期缴税台账!$T$2:$T$501,A5,分期缴税台账!$Q$2:$Q$501,"有效")) | AL5: =IF(AA5="","",MAX(0,AA5-AK5)) | AM5: =IF(OR(A5="",AL5<=0),"",C5&"|"&H5&"|"&(COUNTIFS($C$2:$C$501,C5,$H$2:$H$501,H5,$AL$2:$AL$501,">0",$AC$2:$AC$501,"<"&AC5)+COUNTIFS($C$2:$C$501,C5,$H$2:$H$501,H5,$AL$2:$AL$501,">0",$AC$2:$AC$501,AC5,$A$2:$A$501,"<="&A5)))
B6: =IF(A6="","",A6&"-TAX") | H6: =IF(G6="","",YEAR(G6)) | K6: =IF(OR(E6="",F6="",G6=""),"",IF(E6<>计划参数!$C$2,"",IF(F6="股票期权",IFERROR(LOOKUP(G6,计划参数!$D$12:$D$15,计划参数!$C$12:$C$15),""),IF(F6="限制性股票",计划参数!$C$10,"")))) | L6: =IF(AND(E6=计划参数!$C$2,F6="限制性股票",G6>=计划参数!$D$9),计划参数!$C$9,"") | S6: =IF(OR(A6="",C6="",F6="",G6=""),"",IF(F6="股票期权",IF(OR(I6="",J6="",K6=""),"",(J6-K6)*I6),IF(F6="限制性股票",IF(OR(L6="",M6="",M6<=0,N6=""),"",((L6+J6)/2)*I6-N6*I6/M6),IF(F6="其他股权激励",IF(O6="","",O6),"")))) | T6: =IF(S6="","",MAX(0,S6)) | U6: =IF(T6="","",SUMIFS($T$2:$T$501,$C$2:$C$501,C6,$H$2:$H$501,H6,$G$2:$G$501,"<"&G6)+SUMIFS($T$2:$T$501,$C$2:$C$501,C6,$H$2:$H$501,H6,$G$2:$G$501,G6,$A$2:$A$501,"<"&A6)) | V6: =IF(T6="","",U6+T6) | W6: =IF(V6="","",VLOOKUP(V6,税率及规则!$A$2:$C$8,2,TRUE)) | X6: =IF(V6="","",VLOOKUP(V6,税率及规则!$A$2:$C$8,3,TRUE)) | Y6: =IF(V6="","",MAX(0,V6*W6-X6)) | Z6: =IF(U6="","",MAX(0,U6*VLOOKUP(U6,税率及规则!$A$2:$C$8,2,TRUE)-VLOOKUP(U6,税率及规则!$A$2:$C$8,3,TRUE))) | AA6: =IF(Y6="","",MAX(0,Y6-Z6)) | AB6: =IF(G6="","",G6) | AC6: =IF(AB6="","",IF(DAY(AB6)=DAY(EOMONTH(AB6,0)),EOMONTH(EDATE(AB6,36),0),EDATE(AB6,36))) | AD6: =IF(A6="","",IF(COUNTIF($A$2:$A$501,A6)>1,"异常：事件编号重复",IF(OR(C6="",D6="",E6="",F6="",G6=""),"异常：必填项缺失",IF(AND(F6="其他股权激励",O6=""),"异常：其他股权激励所得缺失",IF(AND(F6<>"其他股权激励",OR(I6="",J6="")),"异常：数量或市场价缺失",IF(AND(F6<>"其他股权激励",OR(I6<=0,J6<0)),"异常：数量或价格无效",IF(AND(F6="限制性股票",OR(M6<=0,N6<0,I6>M6)),"异常：个人获授或出资数据无效",IF(AND(IFERROR(INDEX(计划参数!$J$2:$J$501,MATCH(C6,计划参数!$I$2:$I$501,0)),"")<>"",D6<>IFERROR(INDEX(计划参数!$J$2:$J$501,MATCH(C6,计划参数!$I$2:$I$501,0)),"")),"异常：姓名与员工主数据不一致",IF(S6<0,"异常：原始所得为负，已按0计税",IF(OR(AND(F6="股票期权",K6=""),AND(F6="限制性股票",OR(K6="",L6=""))),"异常：计划参数缺失",IF(COUNTIF(计划参数!$I$2:$I$501,C6)=0,"提示：员工编号未在主数据",IF(Q6<>"已备案","提示：未确认备案","正常")))))))))))) | AF6: =IF(C6="","",IF(COUNTIF($C$2:C6,C6)=1,MAX($AF$1:AF5)+1,"")) | AG6: =IF(C6="","",COUNTIF($C$2:C6,C6)) | AH6: =IF(C6="","",C6&"|"&AG6) | AI6: =IF(OR(A6="",AA6<=0),"",C6&"|"&H6&"|"&(COUNTIFS($C$2:$C$501,C6,$H$2:$H$501,H6,$AA$2:$AA$501,">0",$AC$2:$AC$501,"<"&AC6)+COUNTIFS($C$2:$C$501,C6,$H$2:$H$501,H6,$AA$2:$AA$501,">0",$AC$2:$AC$501,AC6,$A$2:$A$501,"<="&A6))) | AJ6: =IF(OR(A6="",AA6<=0),"",C6&"|"&(COUNTIFS($C$2:$C$501,C6,$AA$2:$AA$501,">0",$AC$2:$AC$501,"<"&AC6)+COUNTIFS($C$2:$C$501,C6,$AA$2:$AA$501,">0",$AC$2:$AC$501,AC6,$A$2:$A$501,"<="&A6))) | AK6: =IF(A6="","",SUMIFS(分期缴税台账!$K$2:$K$501,分期缴税台账!$T$2:$T$501,A6,分期缴税台账!$Q$2:$Q$501,"有效")) | AL6: =IF(AA6="","",MAX(0,AA6-AK6)) | AM6: =IF(OR(A6="",AL6<=0),"",C6&"|"&H6&"|"&(COUNTIFS($C$2:$C$501,C6,$H$2:$H$501,H6,$AL$2:$AL$501,">0",$AC$2:$AC$501,"<"&AC6)+COUNTIFS($C$2:$C$501,C6,$H$2:$H$501,H6,$AL$2:$AL$501,">0",$AC$2:$AC$501,AC6,$A$2:$A$501,"<="&A6)))
B7: =IF(A7="","",A7&"-TAX") | H7: =IF(G7="","",YEAR(G7)) | K7: =IF(OR(E7="",F7="",G7=""),"",IF(E7<>计划参数!$C$2,"",IF(F7="股票期权",IFERROR(LOOKUP(G7,计划参数!$D$12:$D$15,计划参数!$C$12:$C$15),""),IF(F7="限制性股票",计划参数!$C$10,"")))) | L7: =IF(AND(E7=计划参数!$C$2,F7="限制性股票",G7>=计划参数!$D$9),计划参数!$C$9,"") | S7: =IF(OR(A7="",C7="",F7="",G7=""),"",IF(F7="股票期权",IF(OR(I7="",J7="",K7=""),"",(J7-K7)*I7),IF(F7="限制性股票",IF(OR(L7="",M7="",M7<=0,N7=""),"",((L7+J7)/2)*I7-N7*I7/M7),IF(F7="其他股权激励",IF(O7="","",O7),"")))) | T7: =IF(S7="","",MAX(0,S7)) | U7: =IF(T7="","",SUMIFS($T$2:$T$501,$C$2:$C$501,C7,$H$2:$H$501,H7,$G$2:$G$501,"<"&G7)+SUMIFS($T$2:$T$501,$C$2:$C$501,C7,$H$2:$H$501,H7,$G$2:$G$501,G7,$A$2:$A$501,"<"&A7)) | V7: =IF(T7="","",U7+T7) | W7: =IF(V7="","",VLOOKUP(V7,税率及规则!$A$2:$C$8,2,TRUE)) | X7: =IF(V7="","",VLOOKUP(V7,税率及规则!$A$2:$C$8,3,TRUE)) | Y7: =IF(V7="","",MAX(0,V7*W7-X7)) | Z7: =IF(U7="","",MAX(0,U7*VLOOKUP(U7,税率及规则!$A$2:$C$8,2,TRUE)-VLOOKUP(U7,税率及规则!$A$2:$C$8,3,TRUE))) | AA7: =IF(Y7="","",MAX(0,Y7-Z7)) | AB7: =IF(G7="","",G7) | AC7: =IF(AB7="","",IF(DAY(AB7)=DAY(EOMONTH(AB7,0)),EOMONTH(EDATE(AB7,36),0),EDATE(AB7,36))) | AD7: =IF(A7="","",IF(COUNTIF($A$2:$A$501,A7)>1,"异常：事件编号重复",IF(OR(C7="",D7="",E7="",F7="",G7=""),"异常：必填项缺失",IF(AND(F7="其他股权激励",O7=""),"异常：其他股权激励所得缺失",IF(AND(F7<>"其他股权激励",OR(I7="",J7="")),"异常：数量或市场价缺失",IF(AND(F7<>"其他股权激励",OR(I7<=0,J7<0)),"异常：数量或价格无效",IF(AND(F7="限制性股票",OR(M7<=0,N7<0,I7>M7)),"异常：个人获授或出资数据无效",IF(AND(IFERROR(INDEX(计划参数!$J$2:$J$501,MATCH(C7,计划参数!$I$2:$I$501,0)),"")<>"",D7<>IFERROR(INDEX(计划参数!$J$2:$J$501,MATCH(C7,计划参数!$I$2:$I$501,0)),"")),"异常：姓名与员工主数据不一致",IF(S7<0,"异常：原始所得为负，已按0计税",IF(OR(AND(F7="股票期权",K7=""),AND(F7="限制性股票",OR(K7="",L7=""))),"异常：计划参数缺失",IF(COUNTIF(计划参数!$I$2:$I$501,C7)=0,"提示：员工编号未在主数据",IF(Q7<>"已备案","提示：未确认备案","正常")))))))))))) | AF7: =IF(C7="","",IF(COUNTIF($C$2:C7,C7)=1,MAX($AF$1:AF6)+1,"")) | AG7: =IF(C7="","",COUNTIF($C$2:C7,C7)) | AH7: =IF(C7="","",C7&"|"&AG7) | AI7: =IF(OR(A7="",AA7<=0),"",C7&"|"&H7&"|"&(COUNTIFS($C$2:$C$501,C7,$H$2:$H$501,H7,$AA$2:$AA$501,">0",$AC$2:$AC$501,"<"&AC7)+COUNTIFS($C$2:$C$501,C7,$H$2:$H$501,H7,$AA$2:$AA$501,">0",$AC$2:$AC$501,AC7,$A$2:$A$501,"<="&A7))) | AJ7: =IF(OR(A7="",AA7<=0),"",C7&"|"&(COUNTIFS($C$2:$C$501,C7,$AA$2:$AA$501,">0",$AC$2:$AC$501,"<"&AC7)+COUNTIFS($C$2:$C$501,C7,$AA$2:$AA$501,">0",$AC$2:$AC$501,AC7,$A$2:$A$501,"<="&A7))) | AK7: =IF(A7="","",SUMIFS(分期缴税台账!$K$2:$K$501,分期缴税台账!$T$2:$T$501,A7,分期缴税台账!$Q$2:$Q$501,"有效")) | AL7: =IF(AA7="","",MAX(0,AA7-AK7)) | AM7: =IF(OR(A7="",AL7<=0),"",C7&"|"&H7&"|"&(COUNTIFS($C$2:$C$501,C7,$H$2:$H$501,H7,$AL$2:$AL$501,">0",$AC$2:$AC$501,"<"&AC7)+COUNTIFS($C$2:$C$501,C7,$H$2:$H$501,H7,$AL$2:$AL$501,">0",$AC$2:$AC$501,AC7,$A$2:$A$501,"<="&A7)))
B8: =IF(A8="","",A8&"-TAX") | H8: =IF(G8="","",YEAR(G8)) | K8: =IF(OR(E8="",F8="",G8=""),"",IF(E8<>计划参数!$C$2,"",IF(F8="股票期权",IFERROR(LOOKUP(G8,计划参数!$D$12:$D$15,计划参数!$C$12:$C$15),""),IF(F8="限制性股票",计划参数!$C$10,"")))) | L8: =IF(AND(E8=计划参数!$C$2,F8="限制性股票",G8>=计划参数!$D$9),计划参数!$C$9,"") | S8: =IF(OR(A8="",C8="",F8="",G8=""),"",IF(F8="股票期权",IF(OR(I8="",J8="",K8=""),"",(J8-K8)*I8),IF(F8="限制性股票",IF(OR(L8="",M8="",M8<=0,N8=""),"",((L8+J8)/2)*I8-N8*I8/M8),IF(F8="其他股权激励",IF(O8="","",O8),"")))) | T8: =IF(S8="","",MAX(0,S8)) | U8: =IF(T8="","",SUMIFS($T$2:$T$501,$C$2:$C$501,C8,$H$2:$H$501,H8,$G$2:$G$501,"<"&G8)+SUMIFS($T$2:$T$501,$C$2:$C$501,C8,$H$2:$H$501,H8,$G$2:$G$501,G8,$A$2:$A$501,"<"&A8)) | V8: =IF(T8="","",U8+T8) | W8: =IF(V8="","",VLOOKUP(V8,税率及规则!$A$2:$C$8,2,TRUE)) | X8: =IF(V8="","",VLOOKUP(V8,税率及规则!$A$2:$C$8,3,TRUE)) | Y8: =IF(V8="","",MAX(0,V8*W8-X8)) | Z8: =IF(U8="","",MAX(0,U8*VLOOKUP(U8,税率及规则!$A$2:$C$8,2,TRUE)-VLOOKUP(U8,税率及规则!$A$2:$C$8,3,TRUE))) | AA8: =IF(Y8="","",MAX(0,Y8-Z8)) | AB8: =IF(G8="","",G8) | AC8: =IF(AB8="","",IF(DAY(AB8)=DAY(EOMONTH(AB8,0)),EOMONTH(EDATE(AB8,36),0),EDATE(AB8,36))) | AD8: =IF(A8="","",IF(COUNTIF($A$2:$A$501,A8)>1,"异常：事件编号重复",IF(OR(C8="",D8="",E8="",F8="",G8=""),"异常：必填项缺失",IF(AND(F8="其他股权激励",O8=""),"异常：其他股权激励所得缺失",IF(AND(F8<>"其他股权激励",OR(I8="",J8="")),"异常：数量或市场价缺失",IF(AND(F8<>"其他股权激励",OR(I8<=0,J8<0)),"异常：数量或价格无效",IF(AND(F8="限制性股票",OR(M8<=0,N8<0,I8>M8)),"异常：个人获授或出资数据无效",IF(AND(IFERROR(INDEX(计划参数!$J$2:$J$501,MATCH(C8,计划参数!$I$2:$I$501,0)),"")<>"",D8<>IFERROR(INDEX(计划参数!$J$2:$J$501,MATCH(C8,计划参数!$I$2:$I$501,0)),"")),"异常：姓名与员工主数据不一致",IF(S8<0,"异常：原始所得为负，已按0计税",IF(OR(AND(F8="股票期权",K8=""),AND(F8="限制性股票",OR(K8="",L8=""))),"异常：计划参数缺失",IF(COUNTIF(计划参数!$I$2:$I$501,C8)=0,"提示：员工编号未在主数据",IF(Q8<>"已备案","提示：未确认备案","正常")))))))))))) | AF8: =IF(C8="","",IF(COUNTIF($C$2:C8,C8)=1,MAX($AF$1:AF7)+1,"")) | AG8: =IF(C8="","",COUNTIF($C$2:C8,C8)) | AH8: =IF(C8="","",C8&"|"&AG8) | AI8: =IF(OR(A8="",AA8<=0),"",C8&"|"&H8&"|"&(COUNTIFS($C$2:$C$501,C8,$H$2:$H$501,H8,$AA$2:$AA$501,">0",$AC$2:$AC$501,"<"&AC8)+COUNTIFS($C$2:$C$501,C8,$H$2:$H$501,H8,$AA$2:$AA$501,">0",$AC$2:$AC$501,AC8,$A$2:$A$501,"<="&A8))) | AJ8: =IF(OR(A8="",AA8<=0),"",C8&"|"&(COUNTIFS($C$2:$C$501,C8,$AA$2:$AA$501,">0",$AC$2:$AC$501,"<"&AC8)+COUNTIFS($C$2:$C$501,C8,$AA$2:$AA$501,">0",$AC$2:$AC$501,AC8,$A$2:$A$501,"<="&A8))) | AK8: =IF(A8="","",SUMIFS(分期缴税台账!$K$2:$K$501,分期缴税台账!$T$2:$T$501,A8,分期缴税台账!$Q$2:$Q$501,"有效")) | AL8: =IF(AA8="","",MAX(0,AA8-AK8)) | AM8: =IF(OR(A8="",AL8<=0),"",C8&"|"&H8&"|"&(COUNTIFS($C$2:$C$501,C8,$H$2:$H$501,H8,$AL$2:$AL$501,">0",$AC$2:$AC$501,"<"&AC8)+COUNTIFS($C$2:$C$501,C8,$H$2:$H$501,H8,$AL$2:$AL$501,">0",$AC$2:$AC$501,AC8,$A$2:$A$501,"<="&A8)))
B9: =IF(A9="","",A9&"-TAX") | H9: =IF(G9="","",YEAR(G9)) | K9: =IF(OR(E9="",F9="",G9=""),"",IF(E9<>计划参数!$C$2,"",IF(F9="股票期权",IFERROR(LOOKUP(G9,计划参数!$D$12:$D$15,计划参数!$C$12:$C$15),""),IF(F9="限制性股票",计划参数!$C$10,"")))) | L9: =IF(AND(E9=计划参数!$C$2,F9="限制性股票",G9>=计划参数!$D$9),计划参数!$C$9,"") | S9: =IF(OR(A9="",C9="",F9="",G9=""),"",IF(F9="股票期权",IF(OR(I9="",J9="",K9=""),"",(J9-K9)*I9),IF(F9="限制性股票",IF(OR(L9="",M9="",M9<=0,N9=""),"",((L9+J9)/2)*I9-N9*I9/M9),IF(F9="其他股权激励",IF(O9="","",O9),"")))) | T9: =IF(S9="","",MAX(0,S9)) | U9: =IF(T9="","",SUMIFS($T$2:$T$501,$C$2:$C$501,C9,$H$2:$H$501,H9,$G$2:$G$501,"<"&G9)+SUMIFS($T$2:$T$501,$C$2:$C$501,C9,$H$2:$H$501,H9,$G$2:$G$501,G9,$A$2:$A$501,"<"&A9)) | V9: =IF(T9="","",U9+T9) | W9: =IF(V9="","",VLOOKUP(V9,税率及规则!$A$2:$C$8,2,TRUE)) | X9: =IF(V9="","",VLOOKUP(V9,税率及规则!$A$2:$C$8,3,TRUE)) | Y9: =IF(V9="","",MAX(0,V9*W9-X9)) | Z9: =IF(U9="","",MAX(0,U9*VLOOKUP(U9,税率及规则!$A$2:$C$8,2,TRUE)-VLOOKUP(U9,税率及规则!$A$2:$C$8,3,TRUE))) | AA9: =IF(Y9="","",MAX(0,Y9-Z9)) | AB9: =IF(G9="","",G9) | AC9: =IF(AB9="","",IF(DAY(AB9)=DAY(EOMONTH(AB9,0)),EOMONTH(EDATE(AB9,36),0),EDATE(AB9,36))) | AD9: =IF(A9="","",IF(COUNTIF($A$2:$A$501,A9)>1,"异常：事件编号重复",IF(OR(C9="",D9="",E9="",F9="",G9=""),"异常：必填项缺失",IF(AND(F9="其他股权激励",O9=""),"异常：其他股权激励所得缺失",IF(AND(F9<>"其他股权激励",OR(I9="",J9="")),"异常：数量或市场价缺失",IF(AND(F9<>"其他股权激励",OR(I9<=0,J9<0)),"异常：数量或价格无效",IF(AND(F9="限制性股票",OR(M9<=0,N9<0,I9>M9)),"异常：个人获授或出资数据无效",IF(AND(IFERROR(INDEX(计划参数!$J$2:$J$501,MATCH(C9,计划参数!$I$2:$I$501,0)),"")<>"",D9<>IFERROR(INDEX(计划参数!$J$2:$J$501,MATCH(C9,计划参数!$I$2:$I$501,0)),"")),"异常：姓名与员工主数据不一致",IF(S9<0,"异常：原始所得为负，已按0计税",IF(OR(AND(F9="股票期权",K9=""),AND(F9="限制性股票",OR(K9="",L9=""))),"异常：计划参数缺失",IF(COUNTIF(计划参数!$I$2:$I$501,C9)=0,"提示：员工编号未在主数据",IF(Q9<>"已备案","提示：未确认备案","正常")))))))))))) | AF9: =IF(C9="","",IF(COUNTIF($C$2:C9,C9)=1,MAX($AF$1:AF8)+1,"")) | AG9: =IF(C9="","",COUNTIF($C$2:C9,C9)) | AH9: =IF(C9="","",C9&"|"&AG9) | AI9: =IF(OR(A9="",AA9<=0),"",C9&"|"&H9&"|"&(COUNTIFS($C$2:$C$501,C9,$H$2:$H$501,H9,$AA$2:$AA$501,">0",$AC$2:$AC$501,"<"&AC9)+COUNTIFS($C$2:$C$501,C9,$H$2:$H$501,H9,$AA$2:$AA$501,">0",$AC$2:$AC$501,AC9,$A$2:$A$501,"<="&A9))) | AJ9: =IF(OR(A9="",AA9<=0),"",C9&"|"&(COUNTIFS($C$2:$C$501,C9,$AA$2:$AA$501,">0",$AC$2:$AC$501,"<"&AC9)+COUNTIFS($C$2:$C$501,C9,$AA$2:$AA$501,">0",$AC$2:$AC$501,AC9,$A$2:$A$501,"<="&A9))) | AK9: =IF(A9="","",SUMIFS(分期缴税台账!$K$2:$K$501,分期缴税台账!$T$2:$T$501,A9,分期缴税台账!$Q$2:$Q$501,"有效")) | AL9: =IF(AA9="","",MAX(0,AA9-AK9)) | AM9: =IF(OR(A9="",AL9<=0),"",C9&"|"&H9&"|"&(COUNTIFS($C$2:$C$501,C9,$H$2:$H$501,H9,$AL$2:$AL$501,">0",$AC$2:$AC$501,"<"&AC9)+COUNTIFS($C$2:$C$501,C9,$H$2:$H$501,H9,$AL$2:$AL$501,">0",$AC$2:$AC$501,AC9,$A$2:$A$501,"<="&A9)))
B10: =IF(A10="","",A10&"-TAX") | H10: =IF(G10="","",YEAR(G10)) | K10: =IF(OR(E10="",F10="",G10=""),"",IF(E10<>计划参数!$C$2,"",IF(F10="股票期权",IFERROR(LOOKUP(G10,计划参数!$D$12:$D$15,计划参数!$C$12:$C$15),""),IF(F10="限制性股票",计划参数!$C$10,"")))) | L10: =IF(AND(E10=计划参数!$C$2,F10="限制性股票",G10>=计划参数!$D$9),计划参数!$C$9,"") | S10: =IF(OR(A10="",C10="",F10="",G10=""),"",IF(F10="股票期权",IF(OR(I10="",J10="",K10=""),"",(J10-K10)*I10),IF(F10="限制性股票",IF(OR(L10="",M10="",M10<=0,N10=""),"",((L10+J10)/2)*I10-N10*I10/M10),IF(F10="其他股权激励",IF(O10="","",O10),"")))) | T10: =IF(S10="","",MAX(0,S10)) | U10: =IF(T10="","",SUMIFS($T$2:$T$501,$C$2:$C$501,C10,$H$2:$H$501,H10,$G$2:$G$501,"<"&G10)+SUMIFS($T$2:$T$501,$C$2:$C$501,C10,$H$2:$H$501,H10,$G$2:$G$501,G10,$A$2:$A$501,"<"&A10)) | V10: =IF(T10="","",U10+T10) | W10: =IF(V10="","",VLOOKUP(V10,税率及规则!$A$2:$C$8,2,TRUE)) | X10: =IF(V10="","",VLOOKUP(V10,税率及规则!$A$2:$C$8,3,TRUE)) | Y10: =IF(V10="","",MAX(0,V10*W10-X10)) | Z10: =IF(U10="","",MAX(0,U10*VLOOKUP(U10,税率及规则!$A$2:$C$8,2,TRUE)-VLOOKUP(U10,税率及规则!$A$2:$C$8,3,TRUE))) | AA10: =IF(Y10="","",MAX(0,Y10-Z10)) | AB10: =IF(G10="","",G10) | AC10: =IF(AB10="","",IF(DAY(AB10)=DAY(EOMONTH(AB10,0)),EOMONTH(EDATE(AB10,36),0),EDATE(AB10,36))) | AD10: =IF(A10="","",IF(COUNTIF($A$2:$A$501,A10)>1,"异常：事件编号重复",IF(OR(C10="",D10="",E10="",F10="",G10=""),"异常：必填项缺失",IF(AND(F10="其他股权激励",O10=""),"异常：其他股权激励所得缺失",IF(AND(F10<>"其他股权激励",OR(I10="",J10="")),"异常：数量或市场价缺失",IF(AND(F10<>"其他股权激励",OR(I10<=0,J10<0)),"异常：数量或价格无效",IF(AND(F10="限制性股票",OR(M10<=0,N10<0,I10>M10)),"异常：个人获授或出资数据无效",IF(AND(IFERROR(INDEX(计划参数!$J$2:$J$501,MATCH(C10,计划参数!$I$2:$I$501,0)),"")<>"",D10<>IFERROR(INDEX(计划参数!$J$2:$J$501,MATCH(C10,计划参数!$I$2:$I$501,0)),"")),"异常：姓名与员工主数据不一致",IF(S10<0,"异常：原始所得为负，已按0计税",IF(OR(AND(F10="股票期权",K10=""),AND(F10="限制性股票",OR(K10="",L10=""))),"异常：计划参数缺失",IF(COUNTIF(计划参数!$I$2:$I$501,C10)=0,"提示：员工编号未在主数据",IF(Q10<>"已备案","提示：未确认备案","正常")))))))))))) | AF10: =IF(C10="","",IF(COUNTIF($C$2:C10,C10)=1,MAX($AF$1:AF9)+1,"")) | AG10: =IF(C10="","",COUNTIF($C$2:C10,C10)) | AH10: =IF(C10="","",C10&"|"&AG10) | AI10: =IF(OR(A10="",AA10<=0),"",C10&"|"&H10&"|"&(COUNTIFS($C$2:$C$501,C10,$H$2:$H$501,H10,$AA$2:$AA$501,">0",$AC$2:$AC$501,"<"&AC10)+COUNTIFS($C$2:$C$501,C10,$H$2:$H$501,H10,$AA$2:$AA$501,">0",$AC$2:$AC$501,AC10,$A$2:$A$501,"<="&A10))) | AJ10: =IF(OR(A10="",AA10<=0),"",C10&"|"&(COUNTIFS($C$2:$C$501,C10,$AA$2:$AA$501,">0",$AC$2:$AC$501,"<"&AC10)+COUNTIFS($C$2:$C$501,C10,$AA$2:$AA$501,">0",$AC$2:$AC$501,AC10,$A$2:$A$501,"<="&A10))) | AK10: =IF(A10="","",SUMIFS(分期缴税台账!$K$2:$K$501,分期缴税台账!$T$2:$T$501,A10,分期缴税台账!$Q$2:$Q$501,"有效")) | AL10: =IF(AA10="","",MAX(0,AA10-AK10)) | AM10: =IF(OR(A10="",AL10<=0),"",C10&"|"&H10&"|"&(COUNTIFS($C$2:$C$501,C10,$H$2:$H$501,H10,$AL$2:$AL$501,">0",$AC$2:$AC$501,"<"&AC10)+COUNTIFS($C$2:$C$501,C10,$H$2:$H$501,H10,$AL$2:$AL$501,">0",$AC$2:$AC$501,AC10,$A$2:$A$501,"<="&A10)))
B11: =IF(A11="","",A11&"-TAX") | H11: =IF(G11="","",YEAR(G11)) | K11: =IF(OR(E11="",F11="",G11=""),"",IF(E11<>计划参数!$C$2,"",IF(F11="股票期权",IFERROR(LOOKUP(G11,计划参数!$D$12:$D$15,计划参数!$C$12:$C$15),""),IF(F11="限制性股票",计划参数!$C$10,"")))) | L11: =IF(AND(E11=计划参数!$C$2,F11="限制性股票",G11>=计划参数!$D$9),计划参数!$C$9,"") | S11: =IF(OR(A11="",C11="",F11="",G11=""),"",IF(F11="股票期权",IF(OR(I11="",J11="",K11=""),"",(J11-K11)*I11),IF(F11="限制性股票",IF(OR(L11="",M11="",M11<=0,N11=""),"",((L11+J11)/2)*I11-N11*I11/M11),IF(F11="其他股权激励",IF(O11="","",O11),"")))) | T11: =IF(S11="","",MAX(0,S11)) | U11: =IF(T11="","",SUMIFS($T$2:$T$501,$C$2:$C$501,C11,$H$2:$H$501,H11,$G$2:$G$501,"<"&G11)+SUMIFS($T$2:$T$501,$C$2:$C$501,C11,$H$2:$H$501,H11,$G$2:$G$501,G11,$A$2:$A$501,"<"&A11)) | V11: =IF(T11="","",U11+T11) | W11: =IF(V11="","",VLOOKUP(V11,税率及规则!$A$2:$C$8,2,TRUE)) | X11: =IF(V11="","",VLOOKUP(V11,税率及规则!$A$2:$C$8,3,TRUE)) | Y11: =IF(V11="","",MAX(0,V11*W11-X11)) | Z11: =IF(U11="","",MAX(0,U11*VLOOKUP(U11,税率及规则!$A$2:$C$8,2,TRUE)-VLOOKUP(U11,税率及规则!$A$2:$C$8,3,TRUE))) | AA11: =IF(Y11="","",MAX(0,Y11-Z11)) | AB11: =IF(G11="","",G11) | AC11: =IF(AB11="","",IF(DAY(AB11)=DAY(EOMONTH(AB11,0)),EOMONTH(EDATE(AB11,36),0),EDATE(AB11,36))) | AD11: =IF(A11="","",IF(COUNTIF($A$2:$A$501,A11)>1,"异常：事件编号重复",IF(OR(C11="",D11="",E11="",F11="",G11=""),"异常：必填项缺失",IF(AND(F11="其他股权激励",O11=""),"异常：其他股权激励所得缺失",IF(AND(F11<>"其他股权激励",OR(I11="",J11="")),"异常：数量或市场价缺失",IF(AND(F11<>"其他股权激励",OR(I11<=0,J11<0)),"异常：数量或价格无效",IF(AND(F11="限制性股票",OR(M11<=0,N11<0,I11>M11)),"异常：个人获授或出资数据无效",IF(AND(IFERROR(INDEX(计划参数!$J$2:$J$501,MATCH(C11,计划参数!$I$2:$I$501,0)),"")<>"",D11<>IFERROR(INDEX(计划参数!$J$2:$J$501,MATCH(C11,计划参数!$I$2:$I$501,0)),"")),"异常：姓名与员工主数据不一致",IF(S11<0,"异常：原始所得为负，已按0计税",IF(OR(AND(F11="股票期权",K11=""),AND(F11="限制性股票",OR(K11="",L11=""))),"异常：计划参数缺失",IF(COUNTIF(计划参数!$I$2:$I$501,C11)=0,"提示：员工编号未在主数据",IF(Q11<>"已备案","提示：未确认备案","正常")))))))))))) | AF11: =IF(C11="","",IF(COUNTIF($C$2:C11,C11)=1,MAX($AF$1:AF10)+1,"")) | AG11: =IF(C11="","",COUNTIF($C$2:C11,C11)) | AH11: =IF(C11="","",C11&"|"&AG11) | AI11: =IF(OR(A11="",AA11<=0),"",C11&"|"&H11&"|"&(COUNTIFS($C$2:$C$501,C11,$H$2:$H$501,H11,$AA$2:$AA$501,">0",$AC$2:$AC$501,"<"&AC11)+COUNTIFS($C$2:$C$501,C11,$H$2:$H$501,H11,$AA$2:$AA$501,">0",$AC$2:$AC$501,AC11,$A$2:$A$501,"<="&A11))) | AJ11: =IF(OR(A11="",AA11<=0),"",C11&"|"&(COUNTIFS($C$2:$C$501,C11,$AA$2:$AA$501,">0",$AC$2:$AC$501,"<"&AC11)+COUNTIFS($C$2:$C$501,C11,$AA$2:$AA$501,">0",$AC$2:$AC$501,AC11,$A$2:$A$501,"<="&A11))) | AK11: =IF(A11="","",SUMIFS(分期缴税台账!$K$2:$K$501,分期缴税台账!$T$2:$T$501,A11,分期缴税台账!$Q$2:$Q$501,"有效")) | AL11: =IF(AA11="","",MAX(0,AA11-AK11)) | AM11: =IF(OR(A11="",AL11<=0),"",C11&"|"&H11&"|"&(COUNTIFS($C$2:$C$501,C11,$H$2:$H$501,H11,$AL$2:$AL$501,">0",$AC$2:$AC$501,"<"&AC11)+COUNTIFS($C$2:$C$501,C11,$H$2:$H$501,H11,$AL$2:$AL$501,">0",$AC$2:$AC$501,AC11,$A$2:$A$501,"<="&A11)))
B12: =IF(A12="","",A12&"-TAX") | H12: =IF(G12="","",YEAR(G12)) | K12: =IF(OR(E12="",F12="",G12=""),"",IF(E12<>计划参数!$C$2,"",IF(F12="股票期权",IFERROR(LOOKUP(G12,计划参数!$D$12:$D$15,计划参数!$C$12:$C$15),""),IF(F12="限制性股票",计划参数!$C$10,"")))) | L12: =IF(AND(E12=计划参数!$C$2,F12="限制性股票",G12>=计划参数!$D$9),计划参数!$C$9,"") | S12: =IF(OR(A12="",C12="",F12="",G12=""),"",IF(F12="股票期权",IF(OR(I12="",J12="",K12=""),"",(J12-K12)*I12),IF(F12="限制性股票",IF(OR(L12="",M12="",M12<=0,N12=""),"",((L12+J12)/2)*I12-N12*I12/M12),IF(F12="其他股权激励",IF(O12="","",O12),"")))) | T12: =IF(S12="","",MAX(0,S12)) | U12: =IF(T12="","",SUMIFS($T$2:$T$501,$C$2:$C$501,C12,$H$2:$H$501,H12,$G$2:$G$501,"<"&G12)+SUMIFS($T$2:$T$501,$C$2:$C$501,C12,$H$2:$H$501,H12,$G$2:$G$501,G12,$A$2:$A$501,"<"&A12)) | V12: =IF(T12="","",U12+T12) | W12: =IF(V12="","",VLOOKUP(V12,税率及规则!$A$2:$C$8,2,TRUE)) | X12: =IF(V12="","",VLOOKUP(V12,税率及规则!$A$2:$C$8,3,TRUE)) | Y12: =IF(V12="","",MAX(0,V12*W12-X12)) | Z12: =IF(U12="","",MAX(0,U12*VLOOKUP(U12,税率及规则!$A$2:$C$8,2,TRUE)-VLOOKUP(U12,税率及规则!$A$2:$C$8,3,TRUE))) | AA12: =IF(Y12="","",MAX(0,Y12-Z12)) | AB12: =IF(G12="","",G12) | AC12: =IF(AB12="","",IF(DAY(AB12)=DAY(EOMONTH(AB12,0)),EOMONTH(EDATE(AB12,36),0),EDATE(AB12,36))) | AD12: =IF(A12="","",IF(COUNTIF($A$2:$A$501,A12)>1,"异常：事件编号重复",IF(OR(C12="",D12="",E12="",F12="",G12=""),"异常：必填项缺失",IF(AND(F12="其他股权激励",O12=""),"异常：其他股权激励所得缺失",IF(AND(F12<>"其他股权激励",OR(I12="",J12="")),"异常：数量或市场价缺失",IF(AND(F12<>"其他股权激励",OR(I12<=0,J12<0)),"异常：数量或价格无效",IF(AND(F12="限制性股票",OR(M12<=0,N12<0,I12>M12)),"异常：个人获授或出资数据无效",IF(AND(IFERROR(INDEX(计划参数!$J$2:$J$501,MATCH(C12,计划参数!$I$2:$I$501,0)),"")<>"",D12<>IFERROR(INDEX(计划参数!$J$2:$J$501,MATCH(C12,计划参数!$I$2:$I$501,0)),"")),"异常：姓名与员工主数据不一致",IF(S12<0,"异常：原始所得为负，已按0计税",IF(OR(AND(F12="股票期权",K12=""),AND(F12="限制性股票",OR(K12="",L12=""))),"异常：计划参数缺失",IF(COUNTIF(计划参数!$I$2:$I$501,C12)=0,"提示：员工编号未在主数据",IF(Q12<>"已备案","提示：未确认备案","正常")))))))))))) | AF12: =IF(C12="","",IF(COUNTIF($C$2:C12,C12)=1,MAX($AF$1:AF11)+1,"")) | AG12: =IF(C12="","",COUNTIF($C$2:C12,C12)) | AH12: =IF(C12="","",C12&"|"&AG12) | AI12: =IF(OR(A12="",AA12<=0),"",C12&"|"&H12&"|"&(COUNTIFS($C$2:$C$501,C12,$H$2:$H$501,H12,$AA$2:$AA$501,">0",$AC$2:$AC$501,"<"&AC12)+COUNTIFS($C$2:$C$501,C12,$H$2:$H$501,H12,$AA$2:$AA$501,">0",$AC$2:$AC$501,AC12,$A$2:$A$501,"<="&A12))) | AJ12: =IF(OR(A12="",AA12<=0),"",C12&"|"&(COUNTIFS($C$2:$C$501,C12,$AA$2:$AA$501,">0",$AC$2:$AC$501,"<"&AC12)+COUNTIFS($C$2:$C$501,C12,$AA$2:$AA$501,">0",$AC$2:$AC$501,AC12,$A$2:$A$501,"<="&A12))) | AK12: =IF(A12="","",SUMIFS(分期缴税台账!$K$2:$K$501,分期缴税台账!$T$2:$T$501,A12,分期缴税台账!$Q$2:$Q$501,"有效")) | AL12: =IF(AA12="","",MAX(0,AA12-AK12)) | AM12: =IF(OR(A12="",AL12<=0),"",C12&"|"&H12&"|"&(COUNTIFS($C$2:$C$501,C12,$H$2:$H$501,H12,$AL$2:$AL$501,">0",$AC$2:$AC$501,"<"&AC12)+COUNTIFS($C$2:$C$501,C12,$H$2:$H$501,H12,$AL$2:$AL$501,">0",$AC$2:$AC$501,AC12,$A$2:$A$501,"<="&A12)))
B13: =IF(A13="","",A13&"-TAX") | H13: =IF(G13="","",YEAR(G13)) | K13: =IF(OR(E13="",F13="",G13=""),"",IF(E13<>计划参数!$C$2,"",IF(F13="股票期权",IFERROR(LOOKUP(G13,计划参数!$D$12:$D$15,计划参数!$C$12:$C$15),""),IF(F13="限制性股票",计划参数!$C$10,"")))) | L13: =IF(AND(E13=计划参数!$C$2,F13="限制性股票",G13>=计划参数!$D$9),计划参数!$C$9,"") | S13: =IF(OR(A13="",C13="",F13="",G13=""),"",IF(F13="股票期权",IF(OR(I13="",J13="",K13=""),"",(J13-K13)*I13),IF(F13="限制性股票",IF(OR(L13="",M13="",M13<=0,N13=""),"",((L13+J13)/2)*I13-N13*I13/M13),IF(F13="其他股权激励",IF(O13="","",O13),"")))) | T13: =IF(S13="","",MAX(0,S13)) | U13: =IF(T13="","",SUMIFS($T$2:$T$501,$C$2:$C$501,C13,$H$2:$H$501,H13,$G$2:$G$501,"<"&G13)+SUMIFS($T$2:$T$501,$C$2:$C$501,C13,$H$2:$H$501,H13,$G$2:$G$501,G13,$A$2:$A$501,"<"&A13)) | V13: =IF(T13="","",U13+T13) | W13: =IF(V13="","",VLOOKUP(V13,税率及规则!$A$2:$C$8,2,TRUE)) | X13: =IF(V13="","",VLOOKUP(V13,税率及规则!$A$2:$C$8,3,TRUE)) | Y13: =IF(V13="","",MAX(0,V13*W13-X13)) | Z13: =IF(U13="","",MAX(0,U13*VLOOKUP(U13,税率及规则!$A$2:$C$8,2,TRUE)-VLOOKUP(U13,税率及规则!$A$2:$C$8,3,TRUE))) | AA13: =IF(Y13="","",MAX(0,Y13-Z13)) | AB13: =IF(G13="","",G13) | AC13: =IF(AB13="","",IF(DAY(AB13)=DAY(EOMONTH(AB13,0)),EOMONTH(EDATE(AB13,36),0),EDATE(AB13,36))) | AD13: =IF(A13="","",IF(COUNTIF($A$2:$A$501,A13)>1,"异常：事件编号重复",IF(OR(C13="",D13="",E13="",F13="",G13=""),"异常：必填项缺失",IF(AND(F13="其他股权激励",O13=""),"异常：其他股权激励所得缺失",IF(AND(F13<>"其他股权激励",OR(I13="",J13="")),"异常：数量或市场价缺失",IF(AND(F13<>"其他股权激励",OR(I13<=0,J13<0)),"异常：数量或价格无效",IF(AND(F13="限制性股票",OR(M13<=0,N13<0,I13>M13)),"异常：个人获授或出资数据无效",IF(AND(IFERROR(INDEX(计划参数!$J$2:$J$501,MATCH(C13,计划参数!$I$2:$I$501,0)),"")<>"",D13<>IFERROR(INDEX(计划参数!$J$2:$J$501,MATCH(C13,计划参数!$I$2:$I$501,0)),"")),"异常：姓名与员工主数据不一致",IF(S13<0,"异常：原始所得为负，已按0计税",IF(OR(AND(F13="股票期权",K13=""),AND(F13="限制性股票",OR(K13="",L13=""))),"异常：计划参数缺失",IF(COUNTIF(计划参数!$I$2:$I$501,C13)=0,"提示：员工编号未在主数据",IF(Q13<>"已备案","提示：未确认备案","正常")))))))))))) | AF13: =IF(C13="","",IF(COUNTIF($C$2:C13,C13)=1,MAX($AF$1:AF12)+1,"")) | AG13: =IF(C13="","",COUNTIF($C$2:C13,C13)) | AH13: =IF(C13="","",C13&"|"&AG13) | AI13: =IF(OR(A13="",AA13<=0),"",C13&"|"&H13&"|"&(COUNTIFS($C$2:$C$501,C13,$H$2:$H$501,H13,$AA$2:$AA$501,">0",$AC$2:$AC$501,"<"&AC13)+COUNTIFS($C$2:$C$501,C13,$H$2:$H$501,H13,$AA$2:$AA$501,">0",$AC$2:$AC$501,AC13,$A$2:$A$501,"<="&A13))) | AJ13: =IF(OR(A13="",AA13<=0),"",C13&"|"&(COUNTIFS($C$2:$C$501,C13,$AA$2:$AA$501,">0",$AC$2:$AC$501,"<"&AC13)+COUNTIFS($C$2:$C$501,C13,$AA$2:$AA$501,">0",$AC$2:$AC$501,AC13,$A$2:$A$501,"<="&A13))) | AK13: =IF(A13="","",SUMIFS(分期缴税台账!$K$2:$K$501,分期缴税台账!$T$2:$T$501,A13,分期缴税台账!$Q$2:$Q$501,"有效")) | AL13: =IF(AA13="","",MAX(0,AA13-AK13)) | AM13: =IF(OR(A13="",AL13<=0),"",C13&"|"&H13&"|"&(COUNTIFS($C$2:$C$501,C13,$H$2:$H$501,H13,$AL$2:$AL$501,">0",$AC$2:$AC$501,"<"&AC13)+COUNTIFS($C$2:$C$501,C13,$H$2:$H$501,H13,$AL$2:$AL$501,">0",$AC$2:$AC$501,AC13,$A$2:$A$501,"<="&A13)))
B14: =IF(A14="","",A14&"-TAX") | H14: =IF(G14="","",YEAR(G14)) | K14: =IF(OR(E14="",F14="",G14=""),"",IF(E14<>计划参数!$C$2,"",IF(F14="股票期权",IFERROR(LOOKUP(G14,计划参数!$D$12:$D$15,计划参数!$C$12:$C$15),""),IF(F14="限制性股票",计划参数!$C$10,"")))) | L14: =IF(AND(E14=计划参数!$C$2,F14="限制性股票",G14>=计划参数!$D$9),计划参数!$C$9,"") | S14: =IF(OR(A14="",C14="",F14="",G14=""),"",IF(F14="股票期权",IF(OR(I14="",J14="",K14=""),"",(J14-K14)*I14),IF(F14="限制性股票",IF(OR(L14="",M14="",M14<=0,N14=""),"",((L14+J14)/2)*I14-N14*I14/M14),IF(F14="其他股权激励",IF(O14="","",O14),"")))) | T14: =IF(S14="","",MAX(0,S14)) | U14: =IF(T14="","",SUMIFS($T$2:$T$501,$C$2:$C$501,C14,$H$2:$H$501,H14,$G$2:$G$501,"<"&G14)+SUMIFS($T$2:$T$501,$C$2:$C$501,C14,$H$2:$H$501,H14,$G$2:$G$501,G14,$A$2:$A$501,"<"&A14)) | V14: =IF(T14="","",U14+T14) | W14: =IF(V14="","",VLOOKUP(V14,税率及规则!$A$2:$C$8,2,TRUE)) | X14: =IF(V14="","",VLOOKUP(V14,税率及规则!$A$2:$C$8,3,TRUE)) | Y14: =IF(V14="","",MAX(0,V14*W14-X14)) | Z14: =IF(U14="","",MAX(0,U14*VLOOKUP(U14,税率及规则!$A$2:$C$8,2,TRUE)-VLOOKUP(U14,税率及规则!$A$2:$C$8,3,TRUE))) | AA14: =IF(Y14="","",MAX(0,Y14-Z14)) | AB14: =IF(G14="","",G14) | AC14: =IF(AB14="","",IF(DAY(AB14)=DAY(EOMONTH(AB14,0)),EOMONTH(EDATE(AB14,36),0),EDATE(AB14,36))) | AD14: =IF(A14="","",IF(COUNTIF($A$2:$A$501,A14)>1,"异常：事件编号重复",IF(OR(C14="",D14="",E14="",F14="",G14=""),"异常：必填项缺失",IF(AND(F14="其他股权激励",O14=""),"异常：其他股权激励所得缺失",IF(AND(F14<>"其他股权激励",OR(I14="",J14="")),"异常：数量或市场价缺失",IF(AND(F14<>"其他股权激励",OR(I14<=0,J14<0)),"异常：数量或价格无效",IF(AND(F14="限制性股票",OR(M14<=0,N14<0,I14>M14)),"异常：个人获授或出资数据无效",IF(AND(IFERROR(INDEX(计划参数!$J$2:$J$501,MATCH(C14,计划参数!$I$2:$I$501,0)),"")<>"",D14<>IFERROR(INDEX(计划参数!$J$2:$J$501,MATCH(C14,计划参数!$I$2:$I$501,0)),"")),"异常：姓名与员工主数据不一致",IF(S14<0,"异常：原始所得为负，已按0计税",IF(OR(AND(F14="股票期权",K14=""),AND(F14="限制性股票",OR(K14="",L14=""))),"异常：计划参数缺失",IF(COUNTIF(计划参数!$I$2:$I$501,C14)=0,"提示：员工编号未在主数据",IF(Q14<>"已备案","提示：未确认备案","正常")))))))))))) | AF14: =IF(C14="","",IF(COUNTIF($C$2:C14,C14)=1,MAX($AF$1:AF13)+1,"")) | AG14: =IF(C14="","",COUNTIF($C$2:C14,C14)) | AH14: =IF(C14="","",C14&"|"&AG14) | AI14: =IF(OR(A14="",AA14<=0),"",C14&"|"&H14&"|"&(COUNTIFS($C$2:$C$501,C14,$H$2:$H$501,H14,$AA$2:$AA$501,">0",$AC$2:$AC$501,"<"&AC14)+COUNTIFS($C$2:$C$501,C14,$H$2:$H$501,H14,$AA$2:$AA$501,">0",$AC$2:$AC$501,AC14,$A$2:$A$501,"<="&A14))) | AJ14: =IF(OR(A14="",AA14<=0),"",C14&"|"&(COUNTIFS($C$2:$C$501,C14,$AA$2:$AA$501,">0",$AC$2:$AC$501,"<"&AC14)+COUNTIFS($C$2:$C$501,C14,$AA$2:$AA$501,">0",$AC$2:$AC$501,AC14,$A$2:$A$501,"<="&A14))) | AK14: =IF(A14="","",SUMIFS(分期缴税台账!$K$2:$K$501,分期缴税台账!$T$2:$T$501,A14,分期缴税台账!$Q$2:$Q$501,"有效")) | AL14: =IF(AA14="","",MAX(0,AA14-AK14)) | AM14: =IF(OR(A14="",AL14<=0),"",C14&"|"&H14&"|"&(COUNTIFS($C$2:$C$501,C14,$H$2:$H$501,H14,$AL$2:$AL$501,">0",$AC$2:$AC$501,"<"&AC14)+COUNTIFS($C$2:$C$501,C14,$H$2:$H$501,H14,$AL$2:$AL$501,">0",$AC$2:$AC$501,AC14,$A$2:$A$501,"<="&A14)))
B15: =IF(A15="","",A15&"-TAX") | H15: =IF(G15="","",YEAR(G15)) | K15: =IF(OR(E15="",F15="",G15=""),"",IF(E15<>计划参数!$C$2,"",IF(F15="股票期权",IFERROR(LOOKUP(G15,计划参数!$D$12:$D$15,计划参数!$C$12:$C$15),""),IF(F15="限制性股票",计划参数!$C$10,"")))) | L15: =IF(AND(E15=计划参数!$C$2,F15="限制性股票",G15>=计划参数!$D$9),计划参数!$C$9,"") | S15: =IF(OR(A15="",C15="",F15="",G15=""),"",IF(F15="股票期权",IF(OR(I15="",J15="",K15=""),"",(J15-K15)*I15),IF(F15="限制性股票",IF(OR(L15="",M15="",M15<=0,N15=""),"",((L15+J15)/2)*I15-N15*I15/M15),IF(F15="其他股权激励",IF(O15="","",O15),"")))) | T15: =IF(S15="","",MAX(0,S15)) | U15: =IF(T15="","",SUMIFS($T$2:$T$501,$C$2:$C$501,C15,$H$2:$H$501,H15,$G$2:$G$501,"<"&G15)+SUMIFS($T$2:$T$501,$C$2:$C$501,C15,$H$2:$H$501,H15,$G$2:$G$501,G15,$A$2:$A$501,"<"&A15)) | V15: =IF(T15="","",U15+T15) | W15: =IF(V15="","",VLOOKUP(V15,税率及规则!$A$2:$C$8,2,TRUE)) | X15: =IF(V15="","",VLOOKUP(V15,税率及规则!$A$2:$C$8,3,TRUE)) | Y15: =IF(V15="","",MAX(0,V15*W15-X15)) | Z15: =IF(U15="","",MAX(0,U15*VLOOKUP(U15,税率及规则!$A$2:$C$8,2,TRUE)-VLOOKUP(U15,税率及规则!$A$2:$C$8,3,TRUE))) | AA15: =IF(Y15="","",MAX(0,Y15-Z15)) | AB15: =IF(G15="","",G15) | AC15: =IF(AB15="","",IF(DAY(AB15)=DAY(EOMONTH(AB15,0)),EOMONTH(EDATE(AB15,36),0),EDATE(AB15,36))) | AD15: =IF(A15="","",IF(COUNTIF($A$2:$A$501,A15)>1,"异常：事件编号重复",IF(OR(C15="",D15="",E15="",F15="",G15=""),"异常：必填项缺失",IF(AND(F15="其他股权激励",O15=""),"异常：其他股权激励所得缺失",IF(AND(F15<>"其他股权激励",OR(I15="",J15="")),"异常：数量或市场价缺失",IF(AND(F15<>"其他股权激励",OR(I15<=0,J15<0)),"异常：数量或价格无效",IF(AND(F15="限制性股票",OR(M15<=0,N15<0,I15>M15)),"异常：个人获授或出资数据无效",IF(AND(IFERROR(INDEX(计划参数!$J$2:$J$501,MATCH(C15,计划参数!$I$2:$I$501,0)),"")<>"",D15<>IFERROR(INDEX(计划参数!$J$2:$J$501,MATCH(C15,计划参数!$I$2:$I$501,0)),"")),"异常：姓名与员工主数据不一致",IF(S15<0,"异常：原始所得为负，已按0计税",IF(OR(AND(F15="股票期权",K15=""),AND(F15="限制性股票",OR(K15="",L15=""))),"异常：计划参数缺失",IF(COUNTIF(计划参数!$I$2:$I$501,C15)=0,"提示：员工编号未在主数据",IF(Q15<>"已备案","提示：未确认备案","正常")))))))))))) | AF15: =IF(C15="","",IF(COUNTIF($C$2:C15,C15)=1,MAX($AF$1:AF14)+1,"")) | AG15: =IF(C15="","",COUNTIF($C$2:C15,C15)) | AH15: =IF(C15="","",C15&"|"&AG15) | AI15: =IF(OR(A15="",AA15<=0),"",C15&"|"&H15&"|"&(COUNTIFS($C$2:$C$501,C15,$H$2:$H$501,H15,$AA$2:$AA$501,">0",$AC$2:$AC$501,"<"&AC15)+COUNTIFS($C$2:$C$501,C15,$H$2:$H$501,H15,$AA$2:$AA$501,">0",$AC$2:$AC$501,AC15,$A$2:$A$501,"<="&A15))) | AJ15: =IF(OR(A15="",AA15<=0),"",C15&"|"&(COUNTIFS($C$2:$C$501,C15,$AA$2:$AA$501,">0",$AC$2:$AC$501,"<"&AC15)+COUNTIFS($C$2:$C$501,C15,$AA$2:$AA$501,">0",$AC$2:$AC$501,AC15,$A$2:$A$501,"<="&A15))) | AK15: =IF(A15="","",SUMIFS(分期缴税台账!$K$2:$K$501,分期缴税台账!$T$2:$T$501,A15,分期缴税台账!$Q$2:$Q$501,"有效")) | AL15: =IF(AA15="","",MAX(0,AA15-AK15)) | AM15: =IF(OR(A15="",AL15<=0),"",C15&"|"&H15&"|"&(COUNTIFS($C$2:$C$501,C15,$H$2:$H$501,H15,$AL$2:$AL$501,">0",$AC$2:$AC$501,"<"&AC15)+COUNTIFS($C$2:$C$501,C15,$H$2:$H$501,H15,$AL$2:$AL$501,">0",$AC$2:$AC$501,AC15,$A$2:$A$501,"<="&A15)))
... B501: =IF(A501="","",A501&"-TAX") | H501: =IF(G501="","",YEAR(G501)) | K501: =IF(OR(E501="",F501="",G501=""),"",IF(E501<>计划参数!$C$2,"",IF(F501="股票期权",IFERROR(LOOKUP(G501,计划参数!$D$12:$D$15,计划参数!$C$12:$C$15),""),IF(F501="限制性股票",计划参数!$C$10,"")))) | L501: =IF(AND(E501=计划参数!$C$2,F501="限制性股票",G501>=计划参数!$D$9),计划参数!$C$9,"") | S501: =IF(OR(A501="",C501="",F501="",G501=""),"",IF(F501="股票期权",IF(OR(I501="",J501="",K501=""),"",(J501-K501)*I501),IF(F501="限制性股票",IF(OR(L501="",M501="",M501<=0,N501=""),"",((L501+J501)/2)*I501-N501*I501/M501),IF(F501="其他股权激励",IF(O501="","",O501),"")))) | T501: =IF(S501="","",MAX(0,S501)) | U501: =IF(T501="","",SUMIFS($T$2:$T$501,$C$2:$C$501,C501,$H$2:$H$501,H501,$G$2:$G$501,"<"&G501)+SUMIFS($T$2:$T$501,$C$2:$C$501,C501,$H$2:$H$501,H501,$G$2:$G$501,G501,$A$2:$A$501,"<"&A501)) | V501: =IF(T501="","",U501+T501) | W501: =IF(V501="","",VLOOKUP(V501,税率及规则!$A$2:$C$8,2,TRUE)) | X501: =IF(V501="","",VLOOKUP(V501,税率及规则!$A$2:$C$8,3,TRUE)) | Y501: =IF(V501="","",MAX(0,V501*W501-X501)) | Z501: =IF(U501="","",MAX(0,U501*VLOOKUP(U501,税率及规则!$A$2:$C$8,2,TRUE)-VLOOKUP(U501,税率及规则!$A$2:$C$8,3,TRUE))) | AA501: =IF(Y501="","",MAX(0,Y501-Z501)) | AB501: =IF(G501="","",G501) | AC501: =IF(AB501="","",IF(DAY(AB501)=DAY(EOMONTH(AB501,0)),EOMONTH(EDATE(AB501,36),0),EDATE(AB501,36))) | AD501: =IF(A501="","",IF(COUNTIF($A$2:$A$501,A501)>1,"异常：事件编号重复",IF(OR(C501="",D501="",E501="",F501="",G501=""),"异常：必填项缺失",IF(AND(F501="其他股权激励",O501=""),"异常：其他股权激励所得缺失",IF(AND(F501<>"其他股权激励",OR(I501="",J501="")),"异常：数量或市场价缺失",IF(AND(F501<>"其他股权激励",OR(I501<=0,J501<0)),"异常：数量或价格无效",IF(AND(F501="限制性股票",OR(M501<=0,N501<0,I501>M501)),"异常：个人获授或出资数据无效",IF(AND(IFERROR(INDEX(计划参数!$J$2:$J$501,MATCH(C501,计划参数!$I$2:$I$501,0)),"")<>"",D501<>IFERROR(INDEX(计划参数!$J$2:$J$501,MATCH(C501,计划参数!$I$2:$I$501,0)),"")),"异常：姓名与员工主数据不一致",IF(S501<0,"异常：原始所得为负，已按0计税",IF(OR(AND(F501="股票期权",K501=""),AND(F501="限制性股票",OR(K501="",L501=""))),"异常：计划参数缺失",IF(COUNTIF(计划参数!$I$2:$I$501,C501)=0,"提示：员工编号未在主数据",IF(Q501<>"已备案","提示：未确认备案","正常")))))))))))) | AF501: =IF(C501="","",IF(COUNTIF($C$2:C501,C501)=1,MAX($AF$1:AF500)+1,"")) | AG501: =IF(C501="","",COUNTIF($C$2:C501,C501)) | AH501: =IF(C501="","",C501&"|"&AG501) | AI501: =IF(OR(A501="",AA501<=0),"",C501&"|"&H501&"|"&(COUNTIFS($C$2:$C$501,C501,$H$2:$H$501,H501,$AA$2:$AA$501,">0",$AC$2:$AC$501,"<"&AC501)+COUNTIFS($C$2:$C$501,C501,$H$2:$H$501,H501,$AA$2:$AA$501,">0",$AC$2:$AC$501,AC501,$A$2:$A$501,"<="&A501))) | AJ501: =IF(OR(A501="",AA501<=0),"",C501&"|"&(COUNTIFS($C$2:$C$501,C501,$AA$2:$AA$501,">0",$AC$2:$AC$501,"<"&AC501)+COUNTIFS($C$2:$C$501,C501,$AA$2:$AA$501,">0",$AC$2:$AC$501,AC501,$A$2:$A$501,"<="&A501))) | AK501: =IF(A501="","",SUMIFS(分期缴税台账!$K$2:$K$501,分期缴税台账!$T$2:$T$501,A501,分期缴税台账!$Q$2:$Q$501,"有效")) | AL501: =IF(AA501="","",MAX(0,AA501-AK501)) | AM501: =IF(OR(A501="",AL501<=0),"",C501&"|"&H501&"|"&(COUNTIFS($C$2:$C$501,C501,$H$2:$H$501,H501,$AL$2:$AL$501,">0",$AC$2:$AC$501,"<"&AC501)+COUNTIFS($C$2:$C$501,C501,$H$2:$H$501,H501,$AL$2:$AL$501,">0",$AC$2:$AC$501,AC501,$A$2:$A$501,"<="&A501)))

Sheet 年度计税汇总
A1: 员工编号 | B1: 姓名 | C1: 纳税年度 | D1: 股票期权所得 | E1: 限制性股票所得 | F1: 其他股权激励所得 | G1: 年度股权激励应纳税所得额 | H1: 税率 | I1: 速算扣除数 | J1: 年度应纳税额 | K1: 已缴金额 | L1: 未缴金额 | M1: 事件新增税额批次数 | N1: 最早到期事件编号 | O1: 最早到期日 | P1: 状态
A2: DEMO001 | B2: =IF(A2="","",IFERROR(INDEX(激励事件明细!$D$2:$D$501,MATCH(A2,激励事件明细!$C$2:$C$501,0)),"")) -> 演示员工 | C2: 2025 | D2: =IF(OR(A2="",C2=""),"",SUMIFS(激励事件明细!$T$2:$T$501,激励事件明细!$C$2:$C$501,A2,激励事件明细!$H$2:$H$501,C2,激励事件明细!$F$2:$F$501,"股票期权")) -> 162000 | E2: =IF(OR(A2="",C2=""),"",SUMIFS(激励事件明细!$T$2:$T$501,激励事件明细!$C$2:$C$501,A2,激励事件明细!$H$2:$H$501,C2,激励事件明细!$F$2:$F$501,"限制性股票")) -> 337500 | F2: =IF(OR(A2="",C2=""),"",SUMIFS(激励事件明细!$T$2:$T$501,激励事件明细!$C$2:$C$501,A2,激励事件明细!$H$2:$H$501,C2,激励事件明细!$F$2:$F$501,"其他股权激励")) -> 0 | G2: =IF(A2="","",SUM(D2:F2)) -> 499500 | H2: =IF(G2="","",VLOOKUP(G2,税率及规则!$A$2:$C$8,2,TRUE)) -> 0.3 | I2: =IF(G2="","",VLOOKUP(G2,税率及规则!$A$2:$C$8,3,TRUE)) -> 52920 | J2: =IF(G2="","",MAX(0,G2*H2-I2)) -> 96930 | K2: =IF(A2="","",SUMIFS(分期缴税台账!$K$2:$K$501,分期缴税台账!$A$2:$A$501,A2,分期缴税台账!$C$2:$C$501,C2,分期缴税台账!$Q$2:$Q$501,"有效")) -> 0 | L2: =IF(J2="","",MAX(0,J2-K2)) -> 96930 | M2: =IF(A2="","",COUNTIFS(激励事件明细!$C$2:$C$501,A2,激励事件明细!$H$2:$H$501,C2,激励事件明细!$AA$2:$AA$501,">0")) -> 2 | N2: =IF(OR(A2="",C2=""),"",IFERROR(INDEX(激励事件明细!$A$2:$A$501,MATCH(A2&"|"&C2&"|1",激励事件明细!$AM$2:$AM$501,0)),"")) -> DEMO-OPT-001 | O2: =IF(N2="","",IFERROR(INDEX(激励事件明细!$AC$2:$AC$501,MATCH(N2,激励事件明细!$A$2:$A$501,0)),"")) -> 46761 | P2: =IF(A2="","",IF(M2=0,"",IF(K2>J2,"异常：超额缴税",IF(L2=0,"已缴清",IF(AND(O2<TODAY(),L2>0),"逾期未缴","未缴清"))))) -> 未缴清
B3: =IF(A3="","",IFERROR(INDEX(激励事件明细!$D$2:$D$501,MATCH(A3,激励事件明细!$C$2:$C$501,0)),"")) | D3: =IF(OR(A3="",C3=""),"",SUMIFS(激励事件明细!$T$2:$T$501,激励事件明细!$C$2:$C$501,A3,激励事件明细!$H$2:$H$501,C3,激励事件明细!$F$2:$F$501,"股票期权")) | E3: =IF(OR(A3="",C3=""),"",SUMIFS(激励事件明细!$T$2:$T$501,激励事件明细!$C$2:$C$501,A3,激励事件明细!$H$2:$H$501,C3,激励事件明细!$F$2:$F$501,"限制性股票")) | F3: =IF(OR(A3="",C3=""),"",SUMIFS(激励事件明细!$T$2:$T$501,激励事件明细!$C$2:$C$501,A3,激励事件明细!$H$2:$H$501,C3,激励事件明细!$F$2:$F$501,"其他股权激励")) | G3: =IF(A3="","",SUM(D3:F3)) | H3: =IF(G3="","",VLOOKUP(G3,税率及规则!$A$2:$C$8,2,TRUE)) | I3: =IF(G3="","",VLOOKUP(G3,税率及规则!$A$2:$C$8,3,TRUE)) | J3: =IF(G3="","",MAX(0,G3*H3-I3)) | K3: =IF(A3="","",SUMIFS(分期缴税台账!$K$2:$K$501,分期缴税台账!$A$2:$A$501,A3,分期缴税台账!$C$2:$C$501,C3,分期缴税台账!$Q$2:$Q$501,"有效")) | L3: =IF(J3="","",MAX(0,J3-K3)) | M3: =IF(A3="","",COUNTIFS(激励事件明细!$C$2:$C$501,A3,激励事件明细!$H$2:$H$501,C3,激励事件明细!$AA$2:$AA$501,">0")) | N3: =IF(OR(A3="",C3=""),"",IFERROR(INDEX(激励事件明细!$A$2:$A$501,MATCH(A3&"|"&C3&"|1",激励事件明细!$AM$2:$AM$501,0)),"")) | O3: =IF(N3="","",IFERROR(INDEX(激励事件明细!$AC$2:$AC$501,MATCH(N3,激励事件明细!$A$2:$A$501,0)),"")) | P3: =IF(A3="","",IF(M3=0,"",IF(K3>J3,"异常：超额缴税",IF(L3=0,"已缴清",IF(AND(O3<TODAY(),L3>0),"逾期未缴","未缴清")))))
B4: =IF(A4="","",IFERROR(INDEX(激励事件明细!$D$2:$D$501,MATCH(A4,激励事件明细!$C$2:$C$501,0)),"")) | D4: =IF(OR(A4="",C4=""),"",SUMIFS(激励事件明细!$T$2:$T$501,激励事件明细!$C$2:$C$501,A4,激励事件明细!$H$2:$H$501,C4,激励事件明细!$F$2:$F$501,"股票期权")) | E4: =IF(OR(A4="",C4=""),"",SUMIFS(激励事件明细!$T$2:$T$501,激励事件明细!$C$2:$C$501,A4,激励事件明细!$H$2:$H$501,C4,激励事件明细!$F$2:$F$501,"限制性股票")) | F4: =IF(OR(A4="",C4=""),"",SUMIFS(激励事件明细!$T$2:$T$501,激励事件明细!$C$2:$C$501,A4,激励事件明细!$H$2:$H$501,C4,激励事件明细!$F$2:$F$501,"其他股权激励")) | G4: =IF(A4="","",SUM(D4:F4)) | H4: =IF(G4="","",VLOOKUP(G4,税率及规则!$A$2:$C$8,2,TRUE)) | I4: =IF(G4="","",VLOOKUP(G4,税率及规则!$A$2:$C$8,3,TRUE)) | J4: =IF(G4="","",MAX(0,G4*H4-I4)) | K4: =IF(A4="","",SUMIFS(分期缴税台账!$K$2:$K$501,分期缴税台账!$A$2:$A$501,A4,分期缴税台账!$C$2:$C$501,C4,分期缴税台账!$Q$2:$Q$501,"有效")) | L4: =IF(J4="","",MAX(0,J4-K4)) | M4: =IF(A4="","",COUNTIFS(激励事件明细!$C$2:$C$501,A4,激励事件明细!$H$2:$H$501,C4,激励事件明细!$AA$2:$AA$501,">0")) | N4: =IF(OR(A4="",C4=""),"",IFERROR(INDEX(激励事件明细!$A$2:$A$501,MATCH(A4&"|"&C4&"|1",激励事件明细!$AM$2:$AM$501,0)),"")) | O4: =IF(N4="","",IFERROR(INDEX(激励事件明细!$AC$2:$AC$501,MATCH(N4,激励事件明细!$A$2:$A$501,0)),"")) | P4: =IF(A4="","",IF(M4=0,"",IF(K4>J4,"异常：超额缴税",IF(L4=0,"已缴清",IF(AND(O4<TODAY(),L4>0),"逾期未缴","未缴清")))))
B5: =IF(A5="","",IFERROR(INDEX(激励事件明细!$D$2:$D$501,MATCH(A5,激励事件明细!$C$2:$C$501,0)),"")) | D5: =IF(OR(A5="",C5=""),"",SUMIFS(激励事件明细!$T$2:$T$501,激励事件明细!$C$2:$C$501,A5,激励事件明细!$H$2:$H$501,C5,激励事件明细!$F$2:$F$501,"股票期权")) | E5: =IF(OR(A5="",C5=""),"",SUMIFS(激励事件明细!$T$2:$T$501,激励事件明细!$C$2:$C$501,A5,激励事件明细!$H$2:$H$501,C5,激励事件明细!$F$2:$F$501,"限制性股票")) | F5: =IF(OR(A5="",C5=""),"",SUMIFS(激励事件明细!$T$2:$T$501,激励事件明细!$C$2:$C$501,A5,激励事件明细!$H$2:$H$501,C5,激励事件明细!$F$2:$F$501,"其他股权激励")) | G5: =IF(A5="","",SUM(D5:F5)) | H5: =IF(G5="","",VLOOKUP(G5,税率及规则!$A$2:$C$8,2,TRUE)) | I5: =IF(G5="","",VLOOKUP(G5,税率及规则!$A$2:$C$8,3,TRUE)) | J5: =IF(G5="","",MAX(0,G5*H5-I5)) | K5: =IF(A5="","",SUMIFS(分期缴税台账!$K$2:$K$501,分期缴税台账!$A$2:$A$501,A5,分期缴税台账!$C$2:$C$501,C5,分期缴税台账!$Q$2:$Q$501,"有效")) | L5: =IF(J5="","",MAX(0,J5-K5)) | M5: =IF(A5="","",COUNTIFS(激励事件明细!$C$2:$C$501,A5,激励事件明细!$H$2:$H$501,C5,激励事件明细!$AA$2:$AA$501,">0")) | N5: =IF(OR(A5="",C5=""),"",IFERROR(INDEX(激励事件明细!$A$2:$A$501,MATCH(A5&"|"&C5&"|1",激励事件明细!$AM$2:$AM$501,0)),"")) | O5: =IF(N5="","",IFERROR(INDEX(激励事件明细!$AC$2:$AC$501,MATCH(N5,激励事件明细!$A$2:$A$501,0)),"")) | P5: =IF(A5="","",IF(M5=0,"",IF(K5>J5,"异常：超额缴税",IF(L5=0,"已缴清",IF(AND(O5<TODAY(),L5>0),"逾期未缴","未缴清")))))
B6: =IF(A6="","",IFERROR(INDEX(激励事件明细!$D$2:$D$501,MATCH(A6,激励事件明细!$C$2:$C$501,0)),"")) | D6: =IF(OR(A6="",C6=""),"",SUMIFS(激励事件明细!$T$2:$T$501,激励事件明细!$C$2:$C$501,A6,激励事件明细!$H$2:$H$501,C6,激励事件明细!$F$2:$F$501,"股票期权")) | E6: =IF(OR(A6="",C6=""),"",SUMIFS(激励事件明细!$T$2:$T$501,激励事件明细!$C$2:$C$501,A6,激励事件明细!$H$2:$H$501,C6,激励事件明细!$F$2:$F$501,"限制性股票")) | F6: =IF(OR(A6="",C6=""),"",SUMIFS(激励事件明细!$T$2:$T$501,激励事件明细!$C$2:$C$501,A6,激励事件明细!$H$2:$H$501,C6,激励事件明细!$F$2:$F$501,"其他股权激励")) | G6: =IF(A6="","",SUM(D6:F6)) | H6: =IF(G6="","",VLOOKUP(G6,税率及规则!$A$2:$C$8,2,TRUE)) | I6: =IF(G6="","",VLOOKUP(G6,税率及规则!$A$2:$C$8,3,TRUE)) | J6: =IF(G6="","",MAX(0,G6*H6-I6)) | K6: =IF(A6="","",SUMIFS(分期缴税台账!$K$2:$K$501,分期缴税台账!$A$2:$A$501,A6,分期缴税台账!$C$2:$C$501,C6,分期缴税台账!$Q$2:$Q$501,"有效")) | L6: =IF(J6="","",MAX(0,J6-K6)) | M6: =IF(A6="","",COUNTIFS(激励事件明细!$C$2:$C$501,A6,激励事件明细!$H$2:$H$501,C6,激励事件明细!$AA$2:$AA$501,">0")) | N6: =IF(OR(A6="",C6=""),"",IFERROR(INDEX(激励事件明细!$A$2:$A$501,MATCH(A6&"|"&C6&"|1",激励事件明细!$AM$2:$AM$501,0)),"")) | O6: =IF(N6="","",IFERROR(INDEX(激励事件明细!$AC$2:$AC$501,MATCH(N6,激励事件明细!$A$2:$A$501,0)),"")) | P6: =IF(A6="","",IF(M6=0,"",IF(K6>J6,"异常：超额缴税",IF(L6=0,"已缴清",IF(AND(O6<TODAY(),L6>0),"逾期未缴","未缴清")))))
B7: =IF(A7="","",IFERROR(INDEX(激励事件明细!$D$2:$D$501,MATCH(A7,激励事件明细!$C$2:$C$501,0)),"")) | D7: =IF(OR(A7="",C7=""),"",SUMIFS(激励事件明细!$T$2:$T$501,激励事件明细!$C$2:$C$501,A7,激励事件明细!$H$2:$H$501,C7,激励事件明细!$F$2:$F$501,"股票期权")) | E7: =IF(OR(A7="",C7=""),"",SUMIFS(激励事件明细!$T$2:$T$501,激励事件明细!$C$2:$C$501,A7,激励事件明细!$H$2:$H$501,C7,激励事件明细!$F$2:$F$501,"限制性股票")) | F7: =IF(OR(A7="",C7=""),"",SUMIFS(激励事件明细!$T$2:$T$501,激励事件明细!$C$2:$C$501,A7,激励事件明细!$H$2:$H$501,C7,激励事件明细!$F$2:$F$501,"其他股权激励")) | G7: =IF(A7="","",SUM(D7:F7)) | H7: =IF(G7="","",VLOOKUP(G7,税率及规则!$A$2:$C$8,2,TRUE)) | I7: =IF(G7="","",VLOOKUP(G7,税率及规则!$A$2:$C$8,3,TRUE)) | J7: =IF(G7="","",MAX(0,G7*H7-I7)) | K7: =IF(A7="","",SUMIFS(分期缴税台账!$K$2:$K$501,分期缴税台账!$A$2:$A$501,A7,分期缴税台账!$C$2:$C$501,C7,分期缴税台账!$Q$2:$Q$501,"有效")) | L7: =IF(J7="","",MAX(0,J7-K7)) | M7: =IF(A7="","",COUNTIFS(激励事件明细!$C$2:$C$501,A7,激励事件明细!$H$2:$H$501,C7,激励事件明细!$AA$2:$AA$501,">0")) | N7: =IF(OR(A7="",C7=""),"",IFERROR(INDEX(激励事件明细!$A$2:$A$501,MATCH(A7&"|"&C7&"|1",激励事件明细!$AM$2:$AM$501,0)),"")) | O7: =IF(N7="","",IFERROR(INDEX(激励事件明细!$AC$2:$AC$501,MATCH(N7,激励事件明细!$A$2:$A$501,0)),"")) | P7: =IF(A7="","",IF(M7=0,"",IF(K7>J7,"异常：超额缴税",IF(L7=0,"已缴清",IF(AND(O7<TODAY(),L7>0),"逾期未缴","未缴清")))))
B8: =IF(A8="","",IFERROR(INDEX(激励事件明细!$D$2:$D$501,MATCH(A8,激励事件明细!$C$2:$C$501,0)),"")) | D8: =IF(OR(A8="",C8=""),"",SUMIFS(激励事件明细!$T$2:$T$501,激励事件明细!$C$2:$C$501,A8,激励事件明细!$H$2:$H$501,C8,激励事件明细!$F$2:$F$501,"股票期权")) | E8: =IF(OR(A8="",C8=""),"",SUMIFS(激励事件明细!$T$2:$T$501,激励事件明细!$C$2:$C$501,A8,激励事件明细!$H$2:$H$501,C8,激励事件明细!$F$2:$F$501,"限制性股票")) | F8: =IF(OR(A8="",C8=""),"",SUMIFS(激励事件明细!$T$2:$T$501,激励事件明细!$C$2:$C$501,A8,激励事件明细!$H$2:$H$501,C8,激励事件明细!$F$2:$F$501,"其他股权激励")) | G8: =IF(A8="","",SUM(D8:F8)) | H8: =IF(G8="","",VLOOKUP(G8,税率及规则!$A$2:$C$8,2,TRUE)) | I8: =IF(G8="","",VLOOKUP(G8,税率及规则!$A$2:$C$8,3,TRUE)) | J8: =IF(G8="","",MAX(0,G8*H8-I8)) | K8: =IF(A8="","",SUMIFS(分期缴税台账!$K$2:$K$501,分期缴税台账!$A$2:$A$501,A8,分期缴税台账!$C$2:$C$501,C8,分期缴税台账!$Q$2:$Q$501,"有效")) | L8: =IF(J8="","",MAX(0,J8-K8)) | M8: =IF(A8="","",COUNTIFS(激励事件明细!$C$2:$C$501,A8,激励事件明细!$H$2:$H$501,C8,激励事件明细!$AA$2:$AA$501,">0")) | N8: =IF(OR(A8="",C8=""),"",IFERROR(INDEX(激励事件明细!$A$2:$A$501,MATCH(A8&"|"&C8&"|1",激励事件明细!$AM$2:$AM$501,0)),"")) | O8: =IF(N8="","",IFERROR(INDEX(激励事件明细!$AC$2:$AC$501,MATCH(N8,激励事件明细!$A$2:$A$501,0)),"")) | P8: =IF(A8="","",IF(M8=0,"",IF(K8>J8,"异常：超额缴税",IF(L8=0,"已缴清",IF(AND(O8<TODAY(),L8>0),"逾期未缴","未缴清")))))
B9: =IF(A9="","",IFERROR(INDEX(激励事件明细!$D$2:$D$501,MATCH(A9,激励事件明细!$C$2:$C$501,0)),"")) | D9: =IF(OR(A9="",C9=""),"",SUMIFS(激励事件明细!$T$2:$T$501,激励事件明细!$C$2:$C$501,A9,激励事件明细!$H$2:$H$501,C9,激励事件明细!$F$2:$F$501,"股票期权")) | E9: =IF(OR(A9="",C9=""),"",SUMIFS(激励事件明细!$T$2:$T$501,激励事件明细!$C$2:$C$501,A9,激励事件明细!$H$2:$H$501,C9,激励事件明细!$F$2:$F$501,"限制性股票")) | F9: =IF(OR(A9="",C9=""),"",SUMIFS(激励事件明细!$T$2:$T$501,激励事件明细!$C$2:$C$501,A9,激励事件明细!$H$2:$H$501,C9,激励事件明细!$F$2:$F$501,"其他股权激励")) | G9: =IF(A9="","",SUM(D9:F9)) | H9: =IF(G9="","",VLOOKUP(G9,税率及规则!$A$2:$C$8,2,TRUE)) | I9: =IF(G9="","",VLOOKUP(G9,税率及规则!$A$2:$C$8,3,TRUE)) | J9: =IF(G9="","",MAX(0,G9*H9-I9)) | K9: =IF(A9="","",SUMIFS(分期缴税台账!$K$2:$K$501,分期缴税台账!$A$2:$A$501,A9,分期缴税台账!$C$2:$C$501,C9,分期缴税台账!$Q$2:$Q$501,"有效")) | L9: =IF(J9="","",MAX(0,J9-K9)) | M9: =IF(A9="","",COUNTIFS(激励事件明细!$C$2:$C$501,A9,激励事件明细!$H$2:$H$501,C9,激励事件明细!$AA$2:$AA$501,">0")) | N9: =IF(OR(A9="",C9=""),"",IFERROR(INDEX(激励事件明细!$A$2:$A$501,MATCH(A9&"|"&C9&"|1",激励事件明细!$AM$2:$AM$501,0)),"")) | O9: =IF(N9="","",IFERROR(INDEX(激励事件明细!$AC$2:$AC$501,MATCH(N9,激励事件明细!$A$2:$A$501,0)),"")) | P9: =IF(A9="","",IF(M9=0,"",IF(K9>J9,"异常：超额缴税",IF(L9=0,"已缴清",IF(AND(O9<TODAY(),L9>0),"逾期未缴","未缴清")))))
B10: =IF(A10="","",IFERROR(INDEX(激励事件明细!$D$2:$D$501,MATCH(A10,激励事件明细!$C$2:$C$501,0)),"")) | D10: =IF(OR(A10="",C10=""),"",SUMIFS(激励事件明细!$T$2:$T$501,激励事件明细!$C$2:$C$501,A10,激励事件明细!$H$2:$H$501,C10,激励事件明细!$F$2:$F$501,"股票期权")) | E10: =IF(OR(A10="",C10=""),"",SUMIFS(激励事件明细!$T$2:$T$501,激励事件明细!$C$2:$C$501,A10,激励事件明细!$H$2:$H$501,C10,激励事件明细!$F$2:$F$501,"限制性股票")) | F10: =IF(OR(A10="",C10=""),"",SUMIFS(激励事件明细!$T$2:$T$501,激励事件明细!$C$2:$C$501,A10,激励事件明细!$H$2:$H$501,C10,激励事件明细!$F$2:$F$501,"其他股权激励")) | G10: =IF(A10="","",SUM(D10:F10)) | H10: =IF(G10="","",VLOOKUP(G10,税率及规则!$A$2:$C$8,2,TRUE)) | I10: =IF(G10="","",VLOOKUP(G10,税率及规则!$A$2:$C$8,3,TRUE)) | J10: =IF(G10="","",MAX(0,G10*H10-I10)) | K10: =IF(A10="","",SUMIFS(分期缴税台账!$K$2:$K$501,分期缴税台账!$A$2:$A$501,A10,分期缴税台账!$C$2:$C$501,C10,分期缴税台账!$Q$2:$Q$501,"有效")) | L10: =IF(J10="","",MAX(0,J10-K10)) | M10: =IF(A10="","",COUNTIFS(激励事件明细!$C$2:$C$501,A10,激励事件明细!$H$2:$H$501,C10,激励事件明细!$AA$2:$AA$501,">0")) | N10: =IF(OR(A10="",C10=""),"",IFERROR(INDEX(激励事件明细!$A$2:$A$501,MATCH(A10&"|"&C10&"|1",激励事件明细!$AM$2:$AM$501,0)),"")) | O10: =IF(N10="","",IFERROR(INDEX(激励事件明细!$AC$2:$AC$501,MATCH(N10,激励事件明细!$A$2:$A$501,0)),"")) | P10: =IF(A10="","",IF(M10=0,"",IF(K10>J10,"异常：超额缴税",IF(L10=0,"已缴清",IF(AND(O10<TODAY(),L10>0),"逾期未缴","未缴清")))))
B11: =IF(A11="","",IFERROR(INDEX(激励事件明细!$D$2:$D$501,MATCH(A11,激励事件明细!$C$2:$C$501,0)),"")) | D11: =IF(OR(A11="",C11=""),"",SUMIFS(激励事件明细!$T$2:$T$501,激励事件明细!$C$2:$C$501,A11,激励事件明细!$H$2:$H$501,C11,激励事件明细!$F$2:$F$501,"股票期权")) | E11: =IF(OR(A11="",C11=""),"",SUMIFS(激励事件明细!$T$2:$T$501,激励事件明细!$C$2:$C$501,A11,激励事件明细!$H$2:$H$501,C11,激励事件明细!$F$2:$F$501,"限制性股票")) | F11: =IF(OR(A11="",C11=""),"",SUMIFS(激励事件明细!$T$2:$T$501,激励事件明细!$C$2:$C$501,A11,激励事件明细!$H$2:$H$501,C11,激励事件明细!$F$2:$F$501,"其他股权激励")) | G11: =IF(A11="","",SUM(D11:F11)) | H11: =IF(G11="","",VLOOKUP(G11,税率及规则!$A$2:$C$8,2,TRUE)) | I11: =IF(G11="","",VLOOKUP(G11,税率及规则!$A$2:$C$8,3,TRUE)) | J11: =IF(G11="","",MAX(0,G11*H11-I11)) | K11: =IF(A11="","",SUMIFS(分期缴税台账!$K$2:$K$501,分期缴税台账!$A$2:$A$501,A11,分期缴税台账!$C$2:$C$501,C11,分期缴税台账!$Q$2:$Q$501,"有效")) | L11: =IF(J11="","",MAX(0,J11-K11)) | M11: =IF(A11="","",COUNTIFS(激励事件明细!$C$2:$C$501,A11,激励事件明细!$H$2:$H$501,C11,激励事件明细!$AA$2:$AA$501,">0")) | N11: =IF(OR(A11="",C11=""),"",IFERROR(INDEX(激励事件明细!$A$2:$A$501,MATCH(A11&"|"&C11&"|1",激励事件明细!$AM$2:$AM$501,0)),"")) | O11: =IF(N11="","",IFERROR(INDEX(激励事件明细!$AC$2:$AC$501,MATCH(N11,激励事件明细!$A$2:$A$501,0)),"")) | P11: =IF(A11="","",IF(M11=0,"",IF(K11>J11,"异常：超额缴税",IF(L11=0,"已缴清",IF(AND(O11<TODAY(),L11>0),"逾期未缴","未缴清")))))
B12: =IF(A12="","",IFERROR(INDEX(激励事件明细!$D$2:$D$501,MATCH(A12,激励事件明细!$C$2:$C$501,0)),"")) | D12: =IF(OR(A12="",C12=""),"",SUMIFS(激励事件明细!$T$2:$T$501,激励事件明细!$C$2:$C$501,A12,激励事件明细!$H$2:$H$501,C12,激励事件明细!$F$2:$F$501,"股票期权")) | E12: =IF(OR(A12="",C12=""),"",SUMIFS(激励事件明细!$T$2:$T$501,激励事件明细!$C$2:$C$501,A12,激励事件明细!$H$2:$H$501,C12,激励事件明细!$F$2:$F$501,"限制性股票")) | F12: =IF(OR(A12="",C12=""),"",SUMIFS(激励事件明细!$T$2:$T$501,激励事件明细!$C$2:$C$501,A12,激励事件明细!$H$2:$H$501,C12,激励事件明细!$F$2:$F$501,"其他股权激励")) | G12: =IF(A12="","",SUM(D12:F12)) | H12: =IF(G12="","",VLOOKUP(G12,税率及规则!$A$2:$C$8,2,TRUE)) | I12: =IF(G12="","",VLOOKUP(G12,税率及规则!$A$2:$C$8,3,TRUE)) | J12: =IF(G12="","",MAX(0,G12*H12-I12)) | K12: =IF(A12="","",SUMIFS(分期缴税台账!$K$2:$K$501,分期缴税台账!$A$2:$A$501,A12,分期缴税台账!$C$2:$C$501,C12,分期缴税台账!$Q$2:$Q$501,"有效")) | L12: =IF(J12="","",MAX(0,J12-K12)) | M12: =IF(A12="","",COUNTIFS(激励事件明细!$C$2:$C$501,A12,激励事件明细!$H$2:$H$501,C12,激励事件明细!$AA$2:$AA$501,">0")) | N12: =IF(OR(A12="",C12=""),"",IFERROR(INDEX(激励事件明细!$A$2:$A$501,MATCH(A12&"|"&C12&"|1",激励事件明细!$AM$2:$AM$501,0)),"")) | O12: =IF(N12="","",IFERROR(INDEX(激励事件明细!$AC$2:$AC$501,MATCH(N12,激励事件明细!$A$2:$A$501,0)),"")) | P12: =IF(A12="","",IF(M12=0,"",IF(K12>J12,"异常：超额缴税",IF(L12=0,"已缴清",IF(AND(O12<TODAY(),L12>0),"逾期未缴","未缴清")))))
